Workbook
Name 법개: [1]목록상자!$D$2:$D$3
Name 법개: [2]목록상자!$D$2:$D$3

Sheet 고객용 (3)
I3: 장기렌터카 견적서
A6: 고객명 | O6: 작 성 일 | S6: =TODAY() -> 46251
A7: 차종 | O7: 견적서 보관 기간 | S7: 작성일로부터 10일 간 보관
A8: 예상납기 | O8: 견적 번호 | S8: ="A" & LEFT('견적서 보고용'!AD3, 1) & RIGHT('견적서 보고용'!AD3, 1) &"B" & LEFT('견적서 보고용'!AF19, 1) & RIGHT('견적서 보고용'!AF19, 1) -> A03B06
A9: 색상 | O9: 담 당 자 | S9: 이두식 팀장
A10: 옵션 | O10: 연 락 처 | Q10: TEL | S10: 02-547-0303 / 010-9061-3000
Q11: FAX | S11: 02-529-3303
Q12: E-Mail | S12: rent@sdibenefit.com
A14: 매출액 10억 이하인 경우 및 최근 2개년 재무제표 미제출시에 한함  1. 기업의 신용도 판단 목적으로 대표자의 개인신용정보를 조회할 경우, 렌트베네핏은 해당 기업의 대표자에게 조회 사실 및 이유 등을 사전 고지해야 합니다. 2. 렌트베네핏에 상품 견적을 요청한 업무담당자께서는 귀 사의 대표자에게 신용조회가 발생할 수 있음을 반드시 사전 보고해 주시기 바랍니다.
A18: 구분 | B18: 차종 | H18: 수량 | I18: 계약기간 | L18: 차량가격 | P18: 보증금 | S18: 선수금 | V18: 인수가 | Y18: 월대여료
A19: 1
A21: 2
A23: 3
A25: 4
S27: (대당/ 차량소비자가격 " 옵션 및 VAT포함/ 월대여료 : VAT포함
A28: * 상기 견적 금액은 운용대수(계약대수/차량보유대수), 차량가 변동 또는 정부 시책에 따라 변동될 수 있습니다. * 상기 견적 중 선납금을 선택하신 경우는 선납금액을 계약기간으로 균등하게 나눈 금액을 월대여료에서 차감하고 청구됩니다. * 차량 등급별 세부 옵션 사항을 반드시 확인하시기 바라며, 각 차종의 세부 욥션 사항은 차량제조사 홈페이지에서 확인이 가능합니다. * 전기차 지역 보조금 소진 및 정부 정책에 따라 견적 상세 내용이 변경될 수 있으며, 안내되는 보조금 신청 사항 및 서류 접수 내용과 상이할 경우 견적이 취소됩니다.
A32: 월대여료 포함사항 | O32: 대여 조건
A33:  보험료, 차량 검사비, 세금, 공과금 전부 포함 | O33:  약정주행거리 20,000 KM/년 | V33: km/년
A34:  차량 점검, 수리 / 소모품 교체 비용 등 불포함 | O34:  중도해지 수수료율 | T34: 0.35
A35:  유류비, 세차비, 과태료, 범칙금은 임차인 부담 | O35:  연체 이율 | T35: 연 25%
A36: 보험 가입 내용 | O36: 차량 관리 서비스
A37: 운전 범위 | D37: 임직원 | G37: / | H37: 운전자 연령 | K37: 만26세 | O37: 기본제공 사항 | Q37:  차량 법정 검사 대행 | Z37: =D20 -> 0
A38: 대 인 | E38: 무 제 한 | Q38:  차량사고시 사고처리 및 사고수리 | Z38: 자기부담금
A39: 대 물 | E39: 2 억원 | Q39:  차량사고/고장시 긴급 출동서비스 | Z39: 5회/년
A40: 자 기 손 해 | E40: 자상 1억 / 부상 1500만 | O40: 정비 서비스
A41: 자기부담금(CMD) | E41: 30만원 | O41: 서비스별 적용사항 | Q41:  순회정비 차량을 이용한 정기 순회점검 | Y41: =IF($Z$37="미가입",$Z$37, "가입") -> 가입
A42: 무보험차상해 | E42: 2억원 / 1인당 | Q42:  일반정비 (고장수리) 서비스 | Y42: =IF($Z$37="미가입",$Z$37, "가입") -> 가입
A43: 긴급출동 | E43: 5회/년 | Q43:  소모품 교환(오일류, 배터리, 기타) | Y43: =IF($Z$37="미가입",$Z$37, "가입") -> 가입
A44: * 자차손해면책제도(CMD) : 사용자의 귀책으로 인한 사고시 사용자의 자가차량 수리 부담 최대 금액을 한정하는 제도 | Q44:  타이어 교체 | Y44: =IF(Z37 ="가입", '견적서 보고용'!AD11&"본 제공", "미가입") -> 미가입
A46: 비고 | O46: 특약사항
O47:  개별소비세 관련 정부 정책 변경 이후 출고되는 차량의 렌탈료는[개별소비세 변동 금액/계약개월 수]만큼 변동됩니다.
O49:  전기차의 대차는 내연기관 차량으로 제공됩니다.
O50:  전기차 일반형/일반형 정비상품은 순회정비시, 소모품은 에어컨 필터, 와이퍼, 워셔액 교체만 가능하며, 그 외 서비스(소독, 차량 생활흠집, 스캐너 진단)는 희망시 제공됩니다.
B54: 계약시 필요서류 | D54:  법인 : 법인등기부등본(원본), 법인인감증명서(원본), 사업자등록증(사본), 사용인감사용시 사용인감계, 대리인 날인시 위임자, CMS통장사본
K57: 주식회사 | O57: 렌트베네핏
K58: 대표이사 | O58: 신 동 일

Sheet 고객용
I3: 장기렌터카 견적서
A6: 고객명 | E6: ='견적서 보고용'!R1 -> 이희웅 대표님 | O6: 작 성 일 | S6: =TODAY() -> 46251
A7: 차종 | E7: =B19 -> 팰리세이드 (H) 2.5 2WD 프레스티지 9인승 | O7: 견적서 보관 기간 | S7: 작성일로부터 10일 간 보관
A8: 예상납기 | E8: ='견적서 보고용'!AH25 -> 1개월 | O8: 견적 번호 | S8: ="A" & LEFT('견적서 보고용'!AD3, 1) & RIGHT('견적서 보고용'!AD3, 1) &"B" & LEFT('견적서 보고용'!AF19, 1) & RIGHT('견적서 보고용'!AF19, 1) -> A03B06
A9: 색상 | E9: ="[외장] : "&'견적서 보고용'!AL25&", [내장] : "&'견적서 보고용'!AP25 -> [외장] : 화이트, [내장] : 블랙 | O9: 담 당 자 | S9: 이두식 팀장
A10: 옵션 | E10: ='견적서 보고용'!Z27 -> 빌트인캠2, 원격스마트 주차보조 | O10: 연 락 처 | Q10: TEL | S10: 02-547-0303 / 010-9061-3000
Q11: FAX | S11: 02-529-3303
Q12: E-Mail | S12: rent@sdibenefit.com
A14: 매출액 10억 이하인 경우 및 최근 2개년 재무제표 미제출시에 한함  1. 기업의 신용도 판단 목적으로 대표자의 개인신용정보를 조회할 경우, 렌트베네핏은 해당 기업의 대표자에게 조회 사실 및 이유 등을 사전 고지해야 합니다. 2. 렌트베네핏에 상품 견적을 요청한 업무담당자께서는 귀 사의 대표자에게 신용조회가 발생할 수 있음을 반드시 사전 보고해 주시기 바랍니다.
A18: 구분 | B18: 차종 | H18: 수량 | I18: 계약기간 | L18: 차량가격 | P18: 보증금 | S18: 선수금 | V18: 인수가 | Y18: 월대여료
A19: 1 | B19: ='견적서 보고용'!$D$2 -> 팰리세이드 (H) 2.5 2WD 프레스티지 9인승 | H19: 1 | I19: ='견적서 보고용'!E32 -> 48 | L19: ='견적서 보고용'!E7 -> 56680000 | P19: =L19*P20 -> 17004000 | S19: =L19*S20 -> 0 | V19: =L19*V20 -> 31174000 | Y19: ='견적서 보고용'!E41 -> 996000
B20: 정비 | D20: ='견적서 보고용'!E29 -> 가입 | P20: ='견적서 보고용'!E37 -> 0.3 | S20: ='견적서 보고용'!E39 -> 0 | V20: ='견적서 보고용'!E35 -> 0.55
A21: 2 | B21: ='견적서 보고용'!$D$2 -> 팰리세이드 (H) 2.5 2WD 프레스티지 9인승 | H21: 1 | I21: ='견적서 보고용'!J32 -> 48 | L21: ='견적서 보고용'!J7 -> 56680000 | P21: =L21*P22 -> 0 | S21: =L21*S22 -> 0 | V21: =L21*V22 -> 0 | Y21: ='견적서 보고용'!J41 -> 0
B22: 정비 | D22: ='견적서 보고용'!J29 -> 가입 | P22: ='견적서 보고용'!J37 -> 0 | S22: ='견적서 보고용'!J39 -> 0 | V22: ='견적서 보고용'!J35 -> 0
A23: 3 | B23: ='견적서 보고용'!$D$2 -> 팰리세이드 (H) 2.5 2WD 프레스티지 9인승 | H23: 1 | I23: ='견적서 보고용'!O32 -> 48 | L23: ='견적서 보고용'!O7 -> 56680000 | P23: =L23*P24 -> 17004000 | S23: =L23*S24 -> 0 | V23: =L23*V24 -> 34008000 | Y23: ='견적서 보고용'!O41 -> 938500
B24: 정비 | D24: ='견적서 보고용'!O29 -> 가입 | P24: ='견적서 보고용'!O37 -> 0.3 | S24: ='견적서 보고용'!O39 -> 0 | V24: ='견적서 보고용'!O35 -> 0.6
A25: 4 | B25: ='견적서 보고용'!$D$2 -> 팰리세이드 (H) 2.5 2WD 프레스티지 9인승 | H25: 1 | I25: ='견적서 보고용'!T32 -> 48 | L25: ='견적서 보고용'!T7 -> 56680000 | P25: =L25*P26 -> 17004000 | S25: =L25*S26 -> 0 | V25: =L25*V26 -> 31174000 | Y25: ='견적서 보고용'!T41 -> 994000
B26: 정비 | D26: ='견적서 보고용'!T29 -> 가입 | P26: ='견적서 보고용'!T37 -> 0.3 | S26: ='견적서 보고용'!T39 -> 0 | V26: ='견적서 보고용'!T35 -> 0.55
S27: (대당/ 차량소비자가격 " 옵션 및 VAT포함/ 월대여료 : VAT포함
A28: * 상기 견적 금액은 운용대수(계약대수/차량보유대수), 차량가 변동 또는 정부 시책에 따라 변동될 수 있습니다. * 상기 견적 중 선납금을 선택하신 경우는 선납금액을 계약기간으로 균등하게 나눈 금액을 월대여료에서 차감하고 청구됩니다. * 차량 등급별 세부 옵션 사항을 반드시 확인하시기 바라며, 각 차종의 세부 욥션 사항은 차량제조사 홈페이지에서 확인이 가능합니다. * 전기차 지역 보조금 소진 및 정부 정책에 따라 견적 상세 내용이 변경될 수 있으며, 안내되는 보조금 신청 사항 및 서류 접수 내용과 상이할 경우 견적이 취소됩니다.
A32: 월대여료 포함사항 | O32: 대여 조건
A33:  보험료, 차량 검사비, 세금, 공과금 전부 포함 | O33:  약정주행거리 20,000 KM/년 | T33: ='견적서 보고용'!E34 -> 30000 | V33: km/년
A34:  차량 점검, 수리 / 소모품 교체 비용 등 불포함 | O34:  중도해지 수수료율 | T34: 0.35
A35:  유류비, 세차비, 과태료, 범칙금은 임차인 부담 | O35:  연체 이율 | T35: 연 25%
A36: 보험 가입 내용 | O36: 차량 관리 서비스
A37: 운전 범위 | D37: 임직원 | G37: / | H37: 운전자 연령 | K37: 만26세 | O37: 기본제공 사항 | Q37:  차량 법정 검사 대행 | Z37: =D20 -> 가입
A38: 대 인 | E38: 무 제 한 | Q38:  차량사고시 사고처리 및 사고수리 | Z38: 자기부담금
A39: 대 물 | E39: 2 억원 | Q39:  차량사고/고장시 긴급 출동서비스 | Z39: 5회/년
A40: 자 기 손 해 | E40: 자손 1억 / 부상 1500만 | O40: 정비 서비스
A41: 자기부담금(CMD) | E41: 30만원 | O41: 서비스별 적용사항 | Q41:  순회정비 차량을 이용한 정기 순회점검 | Y41: =IF($Z$37="미가입",$Z$37, "가입") -> 가입
A42: 무보험차상해 | E42: 2억원 / 1인당 | Q42:  일반정비 (고장수리) 서비스 | Y42: =IF($Z$37="미가입",$Z$37, "가입") -> 가입
A43: 긴급출동 | E43: 5회/년 | Q43:  소모품 교환(오일류, 배터리, 기타) | Y43: =IF($Z$37="미가입",$Z$37, "가입") -> 가입
A44: * 자차손해면책제도(CMD) : 사용자의 귀책으로 인한 사고시 사용자의 자가차량 수리 부담 최대 금액을 한정하는 제도 | Q44:  타이어 교체 | Y44: =IF(Z37 ="가입", '견적서 보고용'!AD11&"본 제공", "미가입") -> 4본 제공
A46: 비고 | O46: 특약사항
A47: *8000만원 이상 차량 대상으로 법인 고객 선택 시 법인전용 연두색 번호판 적용 대상 | O47:  개별소비세 관련 정부 정책 변경 이후 출고되는 차량의 렌탈료는[개별소비세 변동 금액/계약개월 수]만큼 변동됩니다.
O49:  전기차의 대차는 내연기관 차량으로 제공됩니다.
O50:  전기차 일반형/일반형 정비상품은 순회정비시, 소모품은 에어컨 필터, 와이퍼, 워셔액 교체만 가능하며, 그 외 서비스(소독, 차량 생활흠집, 스캐너 진단)는 희망시 제공됩니다.
B54: 계약시 필요서류 | D54:  법인 : 법인등기부등본(원본), 법인인감증명서(원본), 사업자등록증(사본), 사용인감사용시 사용인감계, 대리인 날인시 위임자, CMS통장사본
K57: 주식회사 | O57: 렌트베네핏
K58: 대표이사 | O58: 신 동 일

Sheet 견적서 보고용
A1: ■ 차량정보 | R1: 이희웅 대표님 | Z1: ■ 렌트베네핏 수수료
A2: 모델명 | D2: 팰리세이드 (H) 2.5 2WD 프레스티지 9인승 | L2: 옵션 | N2: - | AD2: =E7*AD3 -> 1700400 | AI2: =J7*AI3 -> 1700400 | AN2: =O7*AN3 -> 1700400 | AS2: =T7*AS3 -> 1700400
A3: 차량가격 | D3: 56680000 | J3: 연료 | R3: 배기량 | U3: 2500 | X3: cc | Z3: P | AD3: 0.03 | AI3: 0.03 | AN3: 0.03 | AS3: 0.03
A4: 옵션가격 | D4: 0 | R4: 총 차량가격 | U4: =D3+D4 -> 56680000
A5: ■ 캐피탈 | Z5: ■ 딜러 수수료
E6: 1안 | J6: 2안 | O6: 3안 | T6: 기본 계산식 | AD6: =E11*AD7 -> 0 | AI6: =J11*AI7 -> 0 | AN6: =O11*AN7 -> 0 | AS6: =T11*AS7 -> 0
A7: 총 차량가격 | E7: =$D$3 -> 56680000 | J7: =$D$3 -> 56680000 | O7: =$D$3 -> 56680000 | T7: =$D$3 -> 56680000 | Z7: 딜러 인센 | AD7: 0 | AI7: 0 | AN7: 0 | AS7: 0
A8: 할인/면세율 | J8: 0
A9: 할인/면세 | E9: =E7*E8 -> 0 | J9: =J7*J8 -> 0 | O9: =O7*O8 -> 0 | T9: =T7*T8 -> 0
A10: 탁송료 | E10: 360000 | J10: 360000 | O10: 360000 | T10: 360000 | Z10: ■ 타이어
A11: 차량가격 | E11: =E7-E9+E10 -> 57040000 | J11: =J7-J9+J10 -> 57040000 | O11: =O7-O9+O10 -> 57040000 | T11: =T7-T9+T10 -> 57040000 | Z11: 타이어교체 | AD11: 4 | AI11: 4 | AN11: 4 | AS11: 4
A12: 조달원금율 | E12: =E13/E11 -> 0.77352596 | J12: =J13/J11 -> 1.0716326 | O12: =O13/O11 -> 0.77352596 | T12: =T13/T11 -> 0.77352596 | Z12: 타이어 비용 | AD12: 160000 | AI12: 240000 | AN12: 240000 | AS12: 160000
A13: 조달원금 | E13: =E11-E38-E40+E21+E22+E23+E24 -> 44121921 | J13: =J11-J38-J40+J21+J22+J23+J24 -> 61125921 | O13: =O11-O38-O40+O21+O22+O23+O24 -> 44121921 | T13: =T11-T38-T40+T21+T22+T23+T24 -> 44121921 | Z13: 타이어교체 비용 | AD13: =AD11*AD12 -> 640000 | AI13: =AI11*AI12 -> 960000 | AN13: =AN11*AN12 -> 960000 | AS13: =AS11*AS12 -> 640000
A14: 이자부담율 | E14: =IF(E33=5,$AT$21,IF(E33=4,$AP$21,IF(E33=3,$AL$21,IF(E33=2,$AH$21, IF(E33=1, $AD$21))))) -> 0.0614 | J14: =IF(J33=5,$AT$21,IF(J33=4,$AP$21,IF(J33=3,$AL$21,IF(J33=2,$AH$21, IF(J33=1, $AD$21))))) -> 0.0614 | O14: =IF(O33=5,$AT$21,IF(O33=4,$AP$21,IF(O33=3,$AL$21,IF(O33=2,$AH$21, IF(O33=1, $AD$21))))) -> 0.0614 | T14: =IF(T33=5,$AT$21,IF(T33=4,$AP$21,IF(T33=3,$AL$21,IF(T33=2,$AH$21, IF(T33=1, $AD$21))))) -> 0.0614
A15: 조달이자 | E15: =PMT(E14/12, E32, -E13)*E32-E13 -> 5751951.9 | J15: =PMT(J14/12, J32, -J13)*J32-J13 -> 7968677.4 | O15: =PMT(O14/12, O32, -O13)*O32-O13 -> 5751951.9 | T15: =PMT(T14/12, T32, -T13)*T32-T13 -> 5751951.9 | Z15: ■ 차량 정비(정기점검)
A16: 선수금분이자 | E16: =E40*3%*E33 -> 0 | J16: =J40*3%*J33 -> 0 | O16: =O40*3%*O33 -> 0 | T16: =T40*3%*T33 -> 0 | AD16: =AD17*E32 -> 2400000 | AI16: =AI17*J32 -> 2400000 | AN16: =AN17*O32 -> 2400000 | AS16: =AS17*T32 -> 2400000
A17: 월할부금 | E17: =E18/E32 -> 1039039 | J17: =J18/J32 -> 1439470.8 | O17: =O18/O32 -> 1039039 | T17: =T18/T32 -> 1039039 | Z17: 정기점검 비용 | AD17: 50000 | AI17: 50000 | AN17: 50000 | AS17: 50000
A18: 월할부금계 | E18: =E13+E15-E16 -> 49873873 | J18: =J13+J15-J16 -> 69094598 | O18: =O13+O15-O16 -> 49873873 | T18: =T13+T15-T16 -> 49873873
A19: 할부 시 총구입가 | E19: =E11+E15+E16 -> 62791952 | J19: =J11+J15+J16 -> 65008677 | O19: =O11+O15+O16 -> 62791952 | T19: =T11+T15+T16 -> 62791952 | Z19: ■ 이자율 | AF19: 0.06
A20: ■ 등록비용 | AD20: 1년 | AH20: 2년 | AL20: 3년 | AP20: 4년 | AT20: 5년
A21: 취득세 | E21: =ROUNDDOWN(E11/1.1*0.04, -1) -> 2074180 | J21: =ROUNDDOWN(J11/1.1*0.04, -1) -> 2074180 | O21: =ROUNDDOWN(O11/1.1*0.04, -1) -> 2074180 | T21: =ROUNDDOWN(T11/1.1*0.04, -1) -> 2074180 | Z21: 정기점검 | AD21: =AF19+0.31% -> 0.0631 | AH21: =AF19+0.25% -> 0.0625 | AL21: =AF19+0.19% -> 0.0619 | AP21: =AF19+0.14% -> 0.0614 | AT21: =AF19+0.1% -> 0.061
A22: 공채 | E22: =ROUNDDOWN(E11/1.1*3%*16%,-1) -> 248900 | J22: =ROUNDDOWN(J11/1.1*3%*16%,-1) -> 248900 | O22: =ROUNDDOWN(O11/1.1*3%*16%,-1) -> 248900 | T22: =ROUNDDOWN(T11/1.1*3%*16%,-1) -> 248900
A23: 보험 | E23: 800000 | J23: 800000 | O23: 800000 | T23: 800000 | Z23: ■ 선수금 이자율 할인
A24: 보험(자차 보험비) | E24: =CEILING(E7, 10000000) * IF(E7<=10000000, 0.022, IF(E7>=500000000, 0.012, 0.017 - (E7-10000000)*(0.01/(500000000-10000000)) ) ) -> 962840.82 | J24: =CEILING(J7, 10000000) * IF(J7<=10000000, 0.022, IF(J7>=500000000, 0.012, 0.017 - (J7-10000000)*(0.01/(500000000-10000000)) ) ) -> 962840.82 | O24: =CEILING(O7, 10000000) * IF(O7<=10000000, 0.022, IF(O7>=500000000, 0.012, 0.017 - (O7-10000000)*(0.01/(500000000-10000000)) ) ) -> 962840.82 | T24: =CEILING(T7, 10000000) * IF(T7<=10000000, 0.022, IF(T7>=500000000, 0.012, 0.017 - (T7-10000000)*(0.01/(500000000-10000000)) ) ) -> 962840.82 | AD24: =100%-AD25 -> 1 | AH24: 납기 | AL24: 외장 | AP24: 내장
A25: 자동차세 | E25: =IF($U$3<=1600,$U$3*18,IF($U$3<=2500,$U$3*19,IF($U$3>2500,$U$3*24,20000))) -> 47500 | J25: =IF($U$3<=1600,$U$3*18,IF($U$3<=2500,$U$3*19,IF($U$3>2500,$U$3*24,20000))) -> 47500 | O25: =IF($U$3<=1600,$U$3*18,IF($U$3<=2500,$U$3*19,IF($U$3>2500,$U$3*24,20000))) -> 47500 | T25: =IF($U$3<=1600,$U$3*18,IF($U$3<=2500,$U$3*19,IF($U$3>2500,$U$3*24,20000))) -> 47500 | AD25: 0 | AH25: 1개월 | AL25: 화이트 | AP25: 블랙
A26: 등록비용 | E26: 100000 | J26: 100000 | O26: 100000 | T26: 100000 | Z26: ■ 옵션표
A27: ■ 렌트베네핏 총구입가 | Z27: 빌트인캠2, 원격스마트 주차보조
A28: 판관비/노무비 | E28: =E7*3% -> 1700400 | J28: =J7*3% -> 1700400 | O28: 0 | T28: =T7*3% -> 1700400
A29: 정비 | E29: 가입 | J29: 가입 | O29: 가입 | T29: 가입
A30: 총구입가 | E30: =IF(E29="가입",((E23+E24)*E33)+(E25*E33)+E19+E26+E22+E21+AD2+E28+AD6+AD16+AD13,((E23+E24)*E33)+(E25*E33)+E19+E26+E22+E21+AD2+E28+AD6) -> 78897195 | J30: =IF(J29="가입",((J23+J24)*J33)+(J25*J33)+J19+J26+J22+J21+AI2+J28+AI6+AI16+AI13,((J23+J24)*J33)+(J25*J33)+J19+J26+J22+J21+AI2+J28+AI6) -> 81433921 | O30: =IF(O29="가입",((O23+O24)*O33)+(O25*O33)+O19+O26+O22+O21+AN2+O28+AN6+AN16+AN13,((O23+O24)*O33)+(O25*O33)+O19+O26+O22+O21+AN2+O28+AN6) -> 77516795 | T30: =IF(T29="가입",((T23+T24)*T33)+(T25*T33)+T19+T26+T22+T21+AS2+T28+AS6+AS16+AS13,((T23+T24)*T33)+(T25*T33)+T19+T26+T22+T21+AS2+T28+AS6) -> 78897195 | AD30: 1안 | AI30: 2안 | AN30: 3안 | AS30: 4안
A31: ■ 이용정보 | Z31: P 기준 | AD31: =(E44+AD2)/E7 -> 0.031496205 | AI31: =(J44+AI2)/J7 -> -1.4067311 | AN31: =(O44+AN2)/O7 -> 0.057156049 | AS31: =(T44+AS2)/T7 -> 0.03
A32: 렌트기간 | E32: =E33*12 -> 48 | J32: =J33*12 -> 48 | O32: =O33*12 -> 48 | T32: =T33*12 -> 48
A33: 렌트년수 | E33: 4 | J33: 4 | O33: 4 | T33: 4
A34: 약정거리 | E34: 30000 | J34: 20000 | O34: 20000 | T34: 20000
A35: 인수가율 | E35: 0.55 | J35: 0 | O35: 0.6 | T35: 0.55
A36: 인수가 | E36: =E35*E7 -> 31174000 | J36: =J35*J7 -> 0 | O36: =O35*O7 -> 34008000 | T36: =T35*T7 -> 31174000
A37: 보증금율 | E37: 0.3 | J37: 0 | O37: 0.3 | T37: 0.3
A38: 보증금 | E38: =E37*E7 -> 17004000 | J38: =J37*J7 -> 0 | O38: =O37*O7 -> 17004000 | T38: =T37*T7 -> 17004000
A39: 선수금율 | E39: 0 | J39: 0 | O39: 0 | T39: 0
A40: 선수금 | E40: =E39*E7 -> 0 | J40: =J39*J7 -> 0 | O40: =O39*O7 -> 0 | T40: =T39*T7 -> 0
...

Sheet 차량 옵션비교표
A2: 옵션 비교표
A5: 고객명 | E5: 김병현 대표님 | O5: 연 락 처 | Q5: TEL | S5: 02-547-0303 / 010-9061-3000
A6: 작성일 | E6: =TODAY() -> 46251 | Q6: FAX | S6: 02-529-3303
A7: 납기 | Q7: E-Mail | S7: rent@sdibenefit.com
A9: 가격사항
A10: 구분 | E10: 신현용 대표님 | K10: 가격 | P10: 김병현 대표님 | V10: 가격
A11: 차량 | E11: 2023 Genesis G90 | K11: 94450000 | P11: 2024 Genesis G90 | V11: =95400000 -> 95400000
A12: 구동방식 | E12: 48V 일렉트릭 슈퍼차저 | K12: 0 | P12: 48V 일렉트릭 슈퍼차저 | V12: 6000000
A13: 구동방식 | E13: AWD | K13: 3460000 | P13: AWD | V13: 3500000
A14: 외장 색상 | E14: 마우이블랙 | K14: 0 | P14: 마우이블랙 | V14: 0
A15: 내장 색상 | E15: 시그니쳐 디자인 셀렉션 - 옵시디언 블랙 모노톤, 포지드 카본 메탈 G-Matrix 패턴 (시그니쳐 디자인 셀렉션) | K15: =5440000+990000 -> 6430000 | P15: 시그니쳐 디자인 셀렉션 - 옵시디언 블랙 모노톤 | V15: 5500000
A16: 휠 | E16: 20인치 다이아몬드 컷팅 휠 | K16: 990000 | P16: 20인치 다이아몬드 컷팅 휠 | V16: 0
A17: 옵션사항 | E17: 프레스티지 컬렉션 -.앞좌석 컴포트 패키지 -.뒷좌석 컴포트 패키지 I -.하이테크 패키지 -.뒷좌석 컴포트 패키지 II -.이지 클로즈 시스템 -.멀티 챔버 에어 서스펜션 -.능동형 후륜 조향 (RWS) -.시그니쳐 디자인 셀렉션 -.전동식 뒷좌석 듀얼 모니터 | K17: 19290000 | P17: 파퓰러 컬렉션 + 뒷좌석 컴포트 패키지 II -.앞좌석 컴포트 패키지 -.뒷좌석 컴포트 패키지 I -.하이테크 패키지 -.뒷좌석 컴포트 패키지 II | V17: 9500000
A18: 능동형 후륜 조향 멀티 챔버 에어 서스펜션 | E18: O(프레스티지 컬렉션 포함) | K18: 0 | P18: O | V18: 5000000
A19: 빌트인 캠 | E19: O | K19: 790000 | P19: O | V19: 800000
A20: 파노라마 선루프 | E20: O | K20: 1980000 | P20: O | V20: 2000000
A21: 뱅앤올룹슨 사운드 | E21: O | K21: 3960000 | P21: X | V21: 0
A22: 옵션가격 | E22: - | K22: =SUM(K13:O21) -> 36900000 | P22: - | V22: =SUM(V12:Z21) -> 32300000
A23: 총 차량가격 | E23: - | K23: =SUM(K22+K11) -> 131350000 | P23: - | V23: =SUM(V22+V11) -> 127700000
A24: 차액 | V24: =K23-V23 -> 3650000
A25: 추가 내용

Sheet 렌트 리스 비교표
A1: 차량 조건비교표
A3: ='견적서 보고용'!R1 -> 이희웅 대표님 | C3: ="작성일 : " & TEXT(TODAY(), "yyyy-mm-dd") -> 작성일 : 2026-08-17
A4: 구 분 | B4: ='견적서 보고용'!D2 -> 팰리세이드 (H) 2.5 2WD 프레스티지 9인승 | F4: 비고
B5: ="렌트 "&B12&"개월"&CHAR(10)& "보증금 "&TEXT(B7/B6,"0%")&CHAR(10)& "선수금 "&TEXT(B8/B6,"0%")&CHAR(10)& "잔존가치 "&TEXT(B9/B6,"0%") -> 렌트 48개월 보증금 30% 선수금 0% 잔존가치 55% | C5: ="렌트 "&C12&"개월"&CHAR(10)& "보증금 "&TEXT(C7/C6,"0%")&CHAR(10)& "선수금 "&TEXT(C8/C6,"0%")&CHAR(10)& "잔존가치 "&TEXT(C9/C6,"0%") -> 렌트 48개월 보증금 0% 선수금 0% 잔존가치 0% | D5: ="렌트 "&D12&"개월"&CHAR(10)& "보증금 "&TEXT(D7/D6,"0%")&CHAR(10)& "선수금 "&TEXT(D8/D6,"0%")&CHAR(10)& "잔존가치 "&TEXT(D9/D6,"0%") -> 렌트 48개월 보증금 30% 선수금 0% 잔존가치 60% | E5: ="렌트 "&E12&"개월"&CHAR(10)& "보증금 "&TEXT(E7/E6,"0%")&CHAR(10)& "선수금 "&TEXT(E8/E6,"0%")&CHAR(10)& "잔존가치 "&TEXT(E9/E6,"0%") -> 렌트 48개월 보증금 30% 선수금 0% 잔존가치 55%
A6: 차량가격 | B6: ='견적서 보고용'!E7 -> 56680000 | C6: ='견적서 보고용'!J7 -> 56680000 | D6: ='견적서 보고용'!O7 -> 56680000 | E6: ='견적서 보고용'!T7 -> 56680000
A7: 보증금 | B7: ='견적서 보고용'!E38 -> 17004000 | C7: ='견적서 보고용'!J38 -> 0 | D7: ='견적서 보고용'!O38 -> 17004000 | E7: ='견적서 보고용'!T38 -> 17004000
A8: 선수금 | B8: ='견적서 보고용'!E40 -> 0 | C8: ='견적서 보고용'!J40 -> 0 | D8: ='견적서 보고용'!O40 -> 0 | E8: ='견적서 보고용'!T40 -> 0
A9: 잔존가치 | B9: ='견적서 보고용'!E36 -> 31174000 | C9: ='견적서 보고용'!J36 -> 0 | D9: ='견적서 보고용'!O36 -> 34008000 | E9: ='견적서 보고용'!T36 -> 31174000
A10: 출고전 납입액 | B10: =B7+B8 -> 17004000 | C10: =C7+C8 -> 0 | D10: =D7+D8 -> 17004000 | E10: =E7+E8 -> 17004000
A11: 월 납입액 | B11: ='견적서 보고용'!E41 -> 996000 | C11: ='견적서 보고용'!J41 -> 0 | D11: ='견적서 보고용'!O41 -> 938500 | E11: ='견적서 보고용'!T41 -> 994000
A12: 기간(개월) | B12: ='견적서 보고용'!E32 -> 48 | C12: ='견적서 보고용'!J32 -> 48 | D12: ='견적서 보고용'!O32 -> 48 | E12: ='견적서 보고용'!T32 -> 48
A13: 월 납입액계 | B13: =B11*B12 -> 47808000 | C13: =C11*C12 -> 0 | D13: =D11*D12 -> 45048000 | E13: =E11*E12 -> 47712000
A14: 종료 후 납입액 | B14: =B9-B7 -> 14170000 | C14: =C9-C7 -> 0 | D14: =D9-D7 -> 17004000 | E14: =E9-E7 -> 14170000
A15: 예상보험료 | B15: 0 | C15: 0 | D15: 0 | E15: 0
A16: 자동차세 | B16: 0 | C16: 0 | D16: 0 | E16: 0
A17: 총구입가 | B17: =B10+B13+B14+B15+B16 -> 78982000 | C17: =C10+C13+C14+C15+C16 -> 0 | D17: =D10+D13+D14+D15+D16 -> 79056000 | E17: =E10+E13+E14+E15+E16 -> 78886000
A18: 비교금액 | C18: =$B$17-C17 -> 78982000 | D18: =$B$17-D17 -> -74000 | E18: =$B$17-E17 -> 96000
A19: 약정운행거리(년) | B19: =TEXT('견적서 보고용'!E34, "00,000") & "km" -> 30,000km | C19: =TEXT('견적서 보고용'!J34, "00,000") & "KM" -> 20,000KM | D19: =TEXT('견적서 보고용'!O34, "00,000") & "KM" -> 20,000KM | E19: =TEXT('견적서 보고용'!T34, "00,000") & "KM" -> 20,000KM
A20: 정비 | B20: ='견적서 보고용'!E29 -> 가입 | C20: ='견적서 보고용'!J29 -> 가입 | D20: ='견적서 보고용'!O29 -> 가입 | E20: ='견적서 보고용'!T29 -> 가입

Sheet 메모 양식
B3: =CONCATENATE(C6,C8) -> 팰리세이드 (H) 2.5 2WD 프레스티지 9인승[외장] : 화이트, [내장] : 블랙 | E3: =CONCATENATE(F6,F8) -> 팰리세이드 (H) 2.5 2WD 프레스티지 9인승[외장] : 화이트, [내장] : 블랙 | H3: =CONCATENATE(I6,I8) -> 팰리세이드 (H) 2.5 2WD 프레스티지 9인승[외장] : 화이트, [내장] : 블랙 | K3: =CONCATENATE(L6,L8) -> 팰리세이드 (H) 2.5 2WD 프레스티지 9인승[외장] : 화이트, [내장] : 블랙
B5: -. 예상납기 : | C5: =고객용!$E8 -> 1개월 | E5: -. 예상납기 : | F5: =고객용!$E8 -> 1개월 | H5: -. 예상납기 : | I5: =고객용!$E8 -> 1개월 | K5: -. 예상납기 : | L5: =고객용!$E8 -> 1개월
B6: -. 차종 : | C6: =고객용!$B19 -> 팰리세이드 (H) 2.5 2WD 프레스티지 9인승 | E6: -. 차종 : | F6: =고객용!$B21 -> 팰리세이드 (H) 2.5 2WD 프레스티지 9인승 | H6: -. 차종 : | I6: =고객용!$B23 -> 팰리세이드 (H) 2.5 2WD 프레스티지 9인승 | K6: -. 차종 : | L6: =고객용!$B25 -> 팰리세이드 (H) 2.5 2WD 프레스티지 9인승
B7: -. 수량 : | C7: =고객용!$H19 -> 1 | E7: -. 수량 : | F7: =고객용!$H21 -> 1 | H7: -. 수량 : | I7: =고객용!$H23 -> 1 | K7: -. 수량 : | L7: =고객용!$H25 -> 1
B8: -. 색상 : | C8: =고객용!$E9 -> [외장] : 화이트, [내장] : 블랙 | E8: -. 색상 : | F8: =고객용!$E9 -> [외장] : 화이트, [내장] : 블랙 | H8: -. 색상 : | I8: =고객용!$E9 -> [외장] : 화이트, [내장] : 블랙 | K8: -. 색상 : | L8: =고객용!$E9 -> [외장] : 화이트, [내장] : 블랙
B9: -. 옵션 : | C9: =고객용!$E10 -> 빌트인캠2, 원격스마트 주차보조 | E9: -. 옵션 : | F9: =고객용!$E10 -> 빌트인캠2, 원격스마트 주차보조 | H9: -. 옵션 : | I9: =고객용!$E10 -> 빌트인캠2, 원격스마트 주차보조 | K9: -. 옵션 : | L9: =고객용!$E10 -> 빌트인캠2, 원격스마트 주차보조
B10: -. 차량가 : | C10: =고객용!$L19 -> 56680000 | E10: -. 차량가 : | F10: =고객용!$L21 -> 56680000 | H10: -. 차량가 : | I10: =고객용!$L23 -> 56680000 | K10: -. 차량가 : | L10: =고객용!$L25 -> 56680000
B11: -. 기간 : | C11: =고객용!$I19 -> 48 | E11: -. 기간 : | F11: =고객용!$I21 -> 48 | H11: -. 기간 : | I11: =고객용!$I23 -> 48 | K11: -. 기간 : | L11: =고객용!$I25 -> 48
B12: -. 보증금 : | C12: =고객용!$P19 -> 17004000 | E12: -. 보증금 : | F12: =고객용!$P21 -> 0 | H12: -. 보증금 : | I12: =고객용!$P23 -> 17004000 | K12: -. 보증금 : | L12: =고객용!$P25 -> 17004000
B13: -. 선수금 : | C13: =고객용!$S19 -> 0 | E13: -. 선수금 : | F13: =고객용!$S21 -> 0 | H13: -. 선수금 : | I13: =고객용!$S23 -> 0 | K13: -. 선수금 : | L13: =고객용!$S25 -> 0
B14: -. 인수가 : | C14: =고객용!$V19 -> 31174000 | E14: -. 인수가 : | F14: =고객용!$V21 -> 0 | H14: -. 인수가 : | I14: =고객용!$V23 -> 34008000 | K14: -. 인수가 : | L14: =고객용!$V25 -> 31174000
B15: -. 월 대여료 : | C15: =고객용!$Y19 -> 996000 | E15: -. 월 대여료 : | F15: =고객용!$Y21 -> 0 | H15: -. 월 대여료 : | I15: =고객용!$Y23 -> 938500 | K15: -. 월 대여료 : | L15: =고객용!$Y25 -> 994000

Sheet 렌트 견적 비교
A3: 견적서
A6: 고객명 | E6: =고객용!E6 -> 이희웅 대표님 | O6: 작 성 일 | S6: =TODAY() -> 46251
A7: 법인 / 개인 | O7: 견적서 보관 기간 | S7: 작성일로부터 10일 간 보관
A8: 납기 | E8: 3.5개월 | O8: 담 당 자 | S8: 이두식 팀장
A9: 연 락 처 | C9: TEL | O9: 연 락 처 | Q9: TEL | S9: 02-547-0303 / 010-9061-3000
C10: FAX | Q10: FAX | S10: 02-529-3303
C11: E-Mail | Q11: E-Mail | S11: rent@sdibenefit.com
A13: 차 량 | B13: 모델명 | E13: ='견적서 보고용'!D2 -> 팰리세이드 (H) 2.5 2WD 프레스티지 9인승
B14: 선택사양 | E14: ='견적서 보고용'!N2 -> -
B15: 색상 | E15: [외장] 화이트 / [내장] 블랙
A17: 가격사항
A18: 구분 | E18: 신차 구매 | K18: 렌트베네핏 | Q18: 운용리스 | W18: 비고
A19: 순수차량가격 | E19: 15850000 | K19: 15850000 | Q19: =15850000 -> 15850000
A20: 탁송료 | E20: 250000 | K20: 0 | Q20: 250000
A21: 부대비용 | E21: 90000 | K21: 0 | Q21: 90000
A22: 최종 차량가 | E22: =SUM(E19:J21) -> 16190000 | K22: =SUM(K19:P21) -> 15850000 | Q22: =SUM(Q19:V21) -> 16190000
A23: 기간 | E23: ='견적서 보고용'!E32 -> 48 | K23: ='견적서 보고용'!J32 -> 48 | Q23: ='견적서 보고용'!O32 -> 48
A24: 월 렌트료 | E24: 0 | K24: ='견적서 보고용'!J41 -> 0 | Q24: ='견적서 보고용'!O41 -> 938500
A25: 약정주행거리 | E25: 0 | K25: ='견적서 보고용'!J34 -> 20000 | Q25: ='견적서 보고용'!O34 -> 20000
A26: 잔존가치 | E26: 0 | G26: 0 | K26: =M26/K19 -> 0 | M26: ='견적서 보고용'!J36 -> 0 | Q26: =S26/Q22 -> 2.1005559 | S26: ='견적서 보고용'!O36 -> 34008000
A27: 보증금 | E27: 0 | G27: 0 | K27: =M27/K19 -> 0 | M27: ='견적서 보고용'!J38 -> 0 | Q27: =S27/Q22 -> 1.0502779 | S27: ='견적서 보고용'!O38 -> 17004000
A28: 선납금 | E28: =G28/E19 -> 0 | G28: ='견적서 보고용'!E40 -> 0 | K28: =M28/K19 -> 0 | M28: ='견적서 보고용'!J40 -> 0 | Q28: =S28/Q22 -> 0 | S28: ='견적서 보고용'!O40 -> 0
A29: 초기납입금 | E29: =G27+G28 -> 0 | K29: =M27+M28 -> 0 | Q29: =S27+S28 -> 17004000
A30: 렌트료 계 | E30: =E24*E23 -> 0 | K30: =K24*K23 -> 0 | Q30: =Q24*Q23 -> 45048000
A31: 총구입가 | E31: =E22 -> 16190000 | K31: =M26+K30-M27+K29 -> 0 | Q31: =S26+Q30-S27+Q29 -> 79056000
A32: 고객 상담 내용
A33: 레이의 경우 신차 구매시 취득록세 면제
A34: 렌트의 경우 보험료 및 자동차세 포함

Sheet 기본 정비내용
A2: 소모품 | B2: 교환주시 | C2: 부품내역 | D2: 금액
A3: 엔진오일 | B3: 7,000~8,000km | C3: 오일필터+에어 클리너 | D3: 200000
A4: 에어컨 향균필터 | B4: 15,000~20,000km 또는 1년 도래시 | C4: 향균필터 | D4: 40000
A5: 와이퍼 | B5: 1년 도래 시 | D5: 25000
A6: 에어컨 가스 | B6: 1년 도래 시 | C6: 부족할 시 | D6: 250000
A7: 타이어 위치 교환 | B7: 20,000km | C7: 타이어 로테이션 + 휠 밸런스 | D7: 100000
A8: 타이어 공기압 보충 | B8: 매 점검시 | D8: 0
A9: 타이어 교체 | B9: 50,000~70,000km | C9: 타이어*마모 한계선 도래 시 교체 | D9: 600000
A10: 연료 필터 | B10: 40,000km | D10: 60000
A11: 앞 브레이크 패드 / 라이닝 | B11: 40,000km 또는 마모 시 | C11: 앞 디스크 브레이크 패드 | D11: 150000
A12: 뒤 브레이크 패드 / 라이닝 | B12: 70,000km 또는 마모 시 | C12: 뒤 브레이크 라이닝 | D12: 150000
A13: 오일류 | B13: 50,000~60,000km | C13: 변속기/브레이크/파워오일 | D13: 150000
A14: 밸프류 | B14: 50,000km | C14: 에어컨/파워/팬 벨트 | D14: 200000
A15: 전구류 | B15: 필요시 | C15: 라이트/안개 | D15: 50000
A16: 베터리 | B16: 80,000~100,000km | C16: 베터리 | D16: 200000
A17: 점화플러그 | B17: 일반 40,000km / 백금 100,000km | C17: 점화 플러그, 배선 | D17: 50000
A18: 타이밍벨트/워터펌프 | B18: 80,000~90,000km | C18: 타이밍 벨트 세트 | D18: 267450
A19: 부동액 | B19: 100,000km 또는 필요시 | C19: 부동액 | D19: 50000
A20: 기타 보충 | B20: 수시 | C20: - | D20: =SUM(D3:D19) -> 2542450

Sheet Sheet2
E1: 계약기간 | F1: 5
E2: 연간 주행거리 | F2: 20000
E3: 총주행거리 | F3: =F2*F1 -> 100000
A5: A열 | B5: B열(기준km) | C5: C열(기준년) | D5: D열(금액) | E5: E열(교환횟수) | F5: F열(총비용)
A6: 소모품 | B6: 교환km | C6: 교환년 | D6: 금액 | E6: 교환횟수 | F6: 총비용
A7: 엔진오일 | B7: 10000 | C7: 0 | D7: 160000 | E7: =MAX(IF(B7>0, ROUNDDOWN($F$3/B7,0), 0), IF(C7>0, ROUNDDOWN($F$1/C7,0), 0)) -> 10 | F7: =E7*D7 -> 1600000
A8: 에어컨 향균필터 | B8: 15000 | C8: 1 | D8: 40000 | E8: =MAX(IF(B8>0, ROUNDDOWN($F$3/B8,0), 0), IF(C8>0, ROUNDDOWN($F$1/C8,0), 0)) -> 6 | F8: =E8*D8 -> 240000
A9: 와이퍼 | B9: 0 | C9: 1 | D9: 25000 | E9: =MAX(IF(B9>0, ROUNDDOWN($F$3/B9,0), 0), IF(C9>0, ROUNDDOWN($F$1/C9,0), 0)) -> 5 | F9: =E9*D9 -> 125000
A10: 에어컨 가스 | B10: 0 | C10: 1 | D10: 250000 | E10: =MAX(IF(B10>0, ROUNDDOWN($F$3/B10,0), 0), IF(C10>0, ROUNDDOWN($F$1/C10,0), 0)) -> 5 | F10: =E10*D10 -> 1250000
A11: 타이어 위치 교환 | B11: 20000 | C11: 0 | D11: 100000 | E11: =MAX(IF(B11>0, ROUNDDOWN($F$3/B11,0), 0), IF(C11>0, ROUNDDOWN($F$1/C11,0), 0)) -> 5 | F11: =E11*D11 -> 500000
A12: 타이어 교체 | B12: 50000 | C12: 0 | D12: 600000 | E12: =MAX(IF(B12>0, ROUNDDOWN($F$3/B12,0), 0), IF(C12>0, ROUNDDOWN($F$1/C12,0), 0)) -> 2 | F12: =E12*D12 -> 1200000
A13: 연료 필터 | B13: 50000 | C13: 0 | D13: 60000 | E13: =MAX(IF(B13>0, ROUNDDOWN($F$3/B13,0), 0), IF(C13>0, ROUNDDOWN($F$1/C13,0), 0)) -> 2 | F13: =E13*D13 -> 120000
A14: 앞 브레이크 패드 | B14: 40000 | C14: 0 | D14: 150000 | E14: =MAX(IF(B14>0, ROUNDDOWN($F$3/B14,0), 0), IF(C14>0, ROUNDDOWN($F$1/C14,0), 0)) -> 2 | F14: =E14*D14 -> 300000
A15: 뒤 브레이크 패드 | B15: 70000 | C15: 0 | D15: 150000 | E15: =MAX(IF(B15>0, ROUNDDOWN($F$3/B15,0), 0), IF(C15>0, ROUNDDOWN($F$1/C15,0), 0)) -> 1 | F15: =E15*D15 -> 150000
A16: 오일류(변속기 등) | B16: 50000 | C16: 0 | D16: 150000 | E16: =MAX(IF(B16>0, ROUNDDOWN($F$3/B16,0), 0), IF(C16>0, ROUNDDOWN($F$1/C16,0), 0)) -> 2 | F16: =E16*D16 -> 300000
A17: 벨트류 | B17: 50000 | C17: 0 | D17: 200000 | E17: =MAX(IF(B17>0, ROUNDDOWN($F$3/B17,0), 0), IF(C17>0, ROUNDDOWN($F$1/C17,0), 0)) -> 2 | F17: =E17*D17 -> 400000
A18: 전구류 | B18: 0 | C18: 0 | D18: 50000 | E18: =MAX(IF(B18>0, ROUNDDOWN($F$3/B18,0), 0), IF(C18>0, ROUNDDOWN($F$1/C18,0), 0)) -> 0 | F18: =E18*D18 -> 0
... A22: 부동액 | B22: 100000 | C22: 0 | D22: 50000 | E22: =MAX(IF(B22>0, ROUNDDOWN($F$3/B22,0), 0), IF(C22>0, ROUNDDOWN($F$1/C22,0), 0)) -> 1 | F22: =E22*D22 -> 50000
A23: 총금액 | F23: =SUM(F6:F22) -> 6802450
