Workbook
Name 법개: #REF!

Sheet DB_렌트_차량관리
A1: No | B1: 구분 | C1: 운영 | D1: 계약사 | E1: 책임담당자 | F1: 연락처 | G1: 차종 | H1: 차량 사양 | I1: 차량가 | J1: 연식 | K1: 색상 | L1: 유종 | M1: 차대 번호 | N1: 차량 번호 | O1: 옵션 | P1: CC | Q1: 등록일 | R1: 계약일 | S1: 인도 날짜 | T1: 렌트 기간(Y) | U1: 렌트 종료 | V1: 남은 기간 | W1: 운행 거리 | X1: 실무담당자 | Y1: 연락처 | Z1: 지점 | AA1: 출고지 주소 | AB1: 렌트료 개시일 | AC1: 렌트 기간 일수 | AD1: 남은 기간 계산 | AE1: 계약번호 | AF1: 기본가격 | AG1: 할인금액 | AH1: 공급가액 | AI1: 탁송료 | AJ1: 의무보험료 | AK1: 취득세 | AL1: 공채 | AM1: 증지대 | AN1: 번호판대 | AO1: 등록대행료 | AP1: 수수료 | AQ1: 블랙박스 | AR1: 블랙박스 정보 | AS1: 선팅 | AT1: 선팅정보 | AU1: 등록비용 | AV1: 등록비용2 | AW1: 보험 회사 | AX1: 보험가입일 | AY1: 보험료 | AZ1: 자차 보험비 | BA1: 타이어 | BB1: 정기점검 | BD1: 운전자 연령 | BE1: 대인 | BF1: 대물 | BG1: 자손 | BH1: 무보험차상해 | BI1: 고객부담금 | BJ1: 보험종류 | BK1: 긴급출동 | BL1: 사고수리 | BM1: 일반정비 | BN1: 소모품교환 | BO1: 타이어 본수 | BP1: 타이어 | BQ1: 타이어비용 | BR1: 자동차세 | BS1: 차용처 | BT1: 실행일 | BU1: 할부이용금액 | BV1: 기간 | BW1: 월할부금 | BX1: 월할부금 계 | BY1: 총이자 | BZ1: 이자 | CB1: 월 대여료 결제일 | CC1: 계산서발행일 | CD1: 월 납입금 | CE1: 기간 | CF1: 월 납입금 계 | CG1: 보증금 | CH1: 선수금 | CI1: 인수가 | CJ1: P | CK1: 이자 | CL1: 범칙금 E-MAIL | CM1: 범칙금 E-MAIL | CN1: 담당자 휴대전화번호 | CO1: 판관비 | CQ1: 사은품1 | CR1: 사은품1_가격 | CS1: 사은품2 | CT1: 사은품2_가격 | CU1: 사은품3 | CV1: 사은품3_가격 | CW1: 사은품4 | CX1: 사은품4_가격 | CY1: 사은품5 | CZ1: 사은품5_가격 | DA1: 사은품가격 | DB1: 딜러사 | DC1: 담당영업사원 | DD1: 전시장 | DE1: 예금주명 | DF1: 은행 | DG1: 계좌 | DH1: 사업자/주민번호 | DI1: 사업자 주소 | DJ1: 위약금률 | DK1: 연체이율 | DL1: 법인/식별번호 | DM1: 개별소비세(교육세,가산세포함)
A2: 1 | B2: Ray-029 | C2: 사고대차 | D2: 렌트베네핏/사고대차 | E2: 사고대차 | F2: 010-9061-3000 | G2: Ray | H2: 스탠다드 A/T | I2: 12750000 | J2: 2022 | K2: White/Black | L2: 가솔린 | M2: KNACF911BNT284875 | N2: 101호2192 | O2: - | P2: 998 | Q2: 44503 | S2: 44503 | T2: 5 | U2: =IFERROR(S2+AC2, "-") -> 46328 | V2: =IFERROR(DATEDIF(TODAY(), U2, "m"), "-") -> 3 | W2: 20000 | X2: 이두식 | Y2: 010-9061-3000 | AC2: =365*T2 -> 1825 | AQ2: 엠피온 | AT2: 루마 전면 없음/측후면 15% | AU2: 0 | AW2: 렌터카 공제 | AX2: 44503 | AY2: 1153090 | BD2: 만26세 | BE2: 무한대 | BF2: 3억원 | BG2: 1억원/1500만 | BH2: 2억원/1인당 | BI2: 30만원 | BJ2: 누구나 | BK2: 5회/년 | BL2: 가입 | BM2: 가입 | BN2: 브랜드보증 외 사용자 부담 | BO2: 브랜드보증 외 사용자 부담 | BP2: HANKOOK 앞/뒤165 60R14 79H | BR2: =IF(P2<=1600,P2*18,IF(P2<=2500,P2*19,IF(P2>2500,P2*24,20000))) -> 17964 | BS2: 현금 | DI2: 주소 없음
A3: 2 | B3: K5-001 | C3: 사고대차 | D3: 렌트베네핏/사고대차 | E3: 사고대차 | F3: 010-9061-3000 | G3: K5(H) | H3: 하이브리드 프레스티지 베스트셀렉션 | I3: =35020000+530000 -> 35550000 | J3: 2026 | K3: 스노우 화이트펄/블랙 | L3: 가솔린 | M3: KNAG741JBTA060814 | N3: 142호9512 | O3: 빌트인 캠2(45만) | P3: 1999 | Q3: 45995 | S3: 45995 | T3: 5 | U3: =IFERROR(S3+AC3, "-") -> 47820 | V3: =IFERROR(DATEDIF(TODAY(), U3, "m"), "-") -> 52 | W3: 20000 | X3: 이두식 | Y3: 010-9061-3000 | AC3: =365*T3 -> 1825 | AQ3: 빌트인캠 | AR3: 190000 | AT3: 버텍스 전면 35%/1열 15%, 2열, 후면 5% | BD3: 만26세 | BE3: 무한대 | BF3: 3억원 | BG3: 1억원/1500만 | BH3: 2억원/1인당 | BI3: 30만원 | BJ3: 누구나 | BK3: 5회/년 | BL3: 가입 | BM3: 가입 | BN3: 브랜드보증 외 사용자 부담 | BO3: 브랜드보증 외 사용자 부담 | BR3: =IF(P3<=1600,P3*18,IF(P3<=2500,P3*19,IF(P3>2500,P3*24,20000))) -> 37981 | BS3: 현금 | DI3: 주소 없음
A4: 3 | B4: K5-002 | C4: 사고대차 | D4: 렌트베네핏/사고대차 | E4: 사고대차 | F4: 010-9061-3000 | G4: K5(H) | H4: 하이브리드 프레스티지 베스트셀렉션 | I4: =35020000+530000 -> 35550000 | J4: 2026 | K4: 스노우 화이트펄/블랙 | L4: 가솔린 | M4: KNAG741JBTA061764 | N4: 142호9554 | O4: 빌트인 캠2(45만) | P4: 1999 | Q4: 46017 | S4: 46017 | T4: 5 | U4: =IFERROR(S4+AC4, "-") -> 47842 | V4: =IFERROR(DATEDIF(TODAY(), U4, "m"), "-") -> 53 | W4: 20000 | X4: 이두식 | Y4: 010-9061-3000 | AC4: =365*T4 -> 1825 | AQ4: 빌트인캠 | AR4: 190000 | AT4: 버텍스 전면 35%/1열 15%, 2열, 후면 5% | BD4: 만26세 | BE4: 무한대 | BF4: 3억원 | BG4: 1억원/1500만 | BH4: 2억원/1인당 | BI4: 30만원 | BJ4: 누구나 | BK4: 5회/년 | BL4: 가입 | BM4: 가입 | BN4: 브랜드보증 외 사용자 부담 | BO4: 브랜드보증 외 사용자 부담 | BR4: =IF(P4<=1600,P4*18,IF(P4<=2500,P4*19,IF(P4>2500,P4*24,20000))) -> 37981 | BS4: 현금 | DI4: 주소 없음
A5: 4 | B5: K8-007 | C5: 사고대차 | D5: 렌트베네핏/사고대차 | E5: 사고대차 | F5: 010-2294-7638 | G5: K8 | H5: 노블레스 2.5 | I5: =36250000+3860000 -> 40110000 | J5: 2024 | K5: 인터스텔라 그레이/블랙 원톤 | L5: 가솔린 | M5: KNAM241BBRA072481 | N5: 125호8766 | O5: - | P5: 2497 | Q5: 45490 | S5: 45490 | T5: 5 | U5: =IFERROR(S5+AC5, "-") -> 47315 | V5: =IFERROR(DATEDIF(TODAY(), U5, "m"), "-") -> 35 | W5: 20000 | X5: 김경무 | Y5: 010-2294-7638 | AC5: =365*T5 -> 1825 | AQ5: 빌트인캠 | AT5: 버텍스 전면 35%/1열 15%, 2열, 후면 5% | AU5: 1565870 | AW5: 렌터카 공제 | AY5: =2239200-807230 -> 1431970 | BD5: 만26세 | BE5: 무한대 | BF5: 3억원 | BG5: 1억원/1500만 | BH5: 2억원/1인당 | BI5: 30만원 | BJ5: 누구나 | BK5: 5회/년 | BL5: 가입 | BM5: 가입 | BN5: 브랜드보증 외 사용자 부담 | BO5: 브랜드보증 외 사용자 부담 | BP5: NEXEN 225/55R17 | BR5: =IF(P5<=1600,P5*18,IF(P5<=2500,P5*19,IF(P5>2500,P5*24,20000))) -> 47443 | BS5: 현금 | DI5: 주소 없음
A6: 5 | B6: K8-008 | C6: 사고대차 | D6: 렌트베네핏/사고대차 | E6: 조아림 고객님 | F6: 010-9061-3000 | G6: K8 | H6: 노블레스 2.5 | I6: =40880000+3020000 -> 43900000 | J6: 2025 | K6: 인터스텔라 그레이/블랙 원톤 | L6: 가솔린 | M6: KNAM241BBSA081789 | N6: 142호4328 | O6: 드라이브 와이즈(109만), 프리미엄(109만), 헤드업 디스플레이(84만) | P6: 2497 | Q6: 45775 | S6: 45406 | T6: 5 | U6: =IFERROR(S6+AC6, "-") -> 47231 | V6: =IFERROR(DATEDIF(TODAY(), U6, "m"), "-") -> 33 | W6: 20000 | X6: 이두식 | Y6: 010-9061-3000 | AC6: =365*T6 -> 1825 | AQ6: 아이나비 Z7000 | AR6: 190000 | AT6: 버텍스 전면 35%/1열 15%, 2열, 후면 5% | AU6: 1565870 | AW6: 렌터카 공제 | AX6: 250424 | AY6: =2239200-807230 -> 1431970 | BD6: 만26세 | BE6: 무한대 | BF6: 3억원 | BG6: 1억원/1500만 | BH6: 2억원/1인당 | BI6: 30만원 | BJ6: 누구나 | BK6: 5회/년 | BL6: 가입 | BM6: 가입 | BN6: 브랜드보증 외 사용자 부담 | BO6: 브랜드보증 외 사용자 부담 | BP6: NEXEN 225/55R17 | BR6: =IF(P6<=1600,P6*18,IF(P6<=2500,P6*19,IF(P6>2500,P6*24,20000))) -> 47443 | BS6: 현금 | DI6: 주소 없음
A7: 6 | B7: Sorento-001 | C7: 사고대차 | D7: 렌트베네핏/사고대차 | E7: 사고대차 | F7: 010-9061-3000 | G7: Sorento(H) | H7: HEV 2WD 시그니처 5인승 | I7: =46370000+2370000 -> 48740000 | J7: 2026 | K7: 스노우 화이트펄/올리브 브라운 | L7: 가솔린 | M7: KNARK81GBTA477468 | N7: 142호9209 | O7: 드라이브 와이즈 (129만), 스마트 커넥트 (70만), 스노우 화이트펄 외장컬러 (8만), 19인치 휠 (30만) | P7: 1598 | Q7: 46021 | S7: 46021 | T7: 5 | U7: =IFERROR(S7+AC7, "-") -> 47846 | V7: =IFERROR(DATEDIF(TODAY(), U7, "m"), "-") -> 53 | W7: 20000 | X7: 이두식 | Y7: 010-9061-3000 | AC7: =365*T7 -> 1825 | AQ7: 아이나비 Z7000 | AR7: 190000 | AT7: 버텍스 전면 35%/1열 15%, 2열, 후면 5% | BD7: 만26세 | BE7: 무한대 | BF7: 3억원 | BG7: 1억원/1500만 | BH7: 2억원/1인당 | BI7: 30만원 | BJ7: 누구나 | BK7: 5회/년 | BL7: 가입 | BM7: 가입 | BN7: 브랜드보증 외 사용자 부담 | BO7: 브랜드보증 외 사용자 부담 | BR7: =IF(P7<=1600,P7*18,IF(P7<=2500,P7*19,IF(P7>2500,P7*24,20000))) -> 28764 | BS7: 현금 | DI7: 주소 없음
A8: 7 | B8: Grander-007 | C8: 사고대차 | D8: 렌트베네핏/사고대차 | E8: 사고대차 | F8: 010-9061-3000 | G8: 그랜저(H) | H8: 1.6T 프리미엄 2WD 2026 | I8: 48890000 | J8: 2026 | K8: 세레니티 화이트 펄/인디고/브라운투톤 | L8: 가솔린 | M8: KMHN1411BTA133385 | N8: 142호9185 | O8: 파킹어시스트(143만), 플래티넘(129만), 현대스마트센스(84만) | P8: 1600 | Q8: 45979 | S8: 45979 | T8: 5 | U8: =IFERROR(S8+AC8, "-") -> 47804 | V8: =IFERROR(DATEDIF(TODAY(), U8, "m"), "-") -> 51 | W8: 20000 | X8: 이두식 | Y8: 010-9061-3000 | AC8: =365*T8 -> 1825 | AQ8: 빌트인캠 | AT8: 버텍스 전면 35%/측후면 15% | AW8: 렌터카 공제 | BD8: 만26세 | BE8: 무한대 | BF8: 3억원 | BG8: 1억원/1500만 | BH8: 2억원/1인당 | BI8: 30만원 | BJ8: 누구나 | BK8: 5회/년 | BL8: 가입 | BM8: 가입 | BN8: 브랜드보증 외 사용자 부담 | BO8: 브랜드보증 외 사용자 부담 | BR8: =IF(P8<=1600,P8*18,IF(P8<=2500,P8*19,IF(P8>2500,P8*24,20000))) -> 28800 | BS8: 현금 | DI8: 주소 없음
A9: 8 | B9: G80-003 | C9: 사고대차 | D9: 렌트베네핏/사고대차 | E9: 사고대차 | F9: 010-9061-3000 | G9: G80 | H9: 3.5T AWD | I9: 71450000 | J9: 2023 | K9: 비크블랙/브라운 | L9: 가솔린 | M9: KMTGC41DDPU167545 | N9: 125호5289 | O9: - | P9: 3497 | Q9: 44889 | S9: 44889 | T9: 5 | U9: =IFERROR(S9+AC9, "-") -> 46714 | V9: =IFERROR(DATEDIF(TODAY(), U9, "m"), "-") -> 16 | W9: 20000 | X9: 이두식 | Y9: 010-9061-3000 | AC9: =365*T9 -> 1825 | AQ9: 빌트인캠 | AT9: 버텍스 전면 35%/측후면 15% | AU9: 2936914 | AW9: 렌터카 공제 | AY9: 1198330 | BD9: 만26세 | BE9: 무한대 | BF9: 5억 | BG9: 2억/3천만 | BH9: 2억원/1인당 | BI9: 50만원 | BJ9: 누구나 | BK9: 5회/년 | BL9: 가입 | BM9: 가입 | BN9: 브랜드보증 외 사용자 부담 | BO9: 브랜드보증 외 사용자 부담 | BR9: =IF(P9<=1600,P9*18,IF(P9<=2500,P9*19,IF(P9>2500,P9*24,20000))) -> 83928 | BS9: 현금 | DI9: 주소 없음
A10: 9 | B10: GV80-005 | C10: 사고대차 | D10: 렌트베네핏/사고대차 | E10: 사고대차 | F10: 010-9061-3000 | G10: GV80 | H10: 2.5T AWD 19인치 SDS1 | I10: =73450000+5950000 -> 79400000 | J10: 2026 | K10: 비크블랙 / 스모키그린(어스브라운 시트) | L10: 가솔린 | M10: KMTHA81BDTU313089 | N10: 142호9513 | O10: 드라이빙 어시스턴스 패키지2(270만), 드라이빙 어시스턴스 패키지(195만), 헤드업디스플레이130만) | P10: 2499 | Q10: 45995 | S10: 45995 | T10: 5 | U10: =IFERROR(S10+AC10, "-") -> 47820 | V10: =IFERROR(DATEDIF(TODAY(), U10, "m"), "-") -> 52 | W10: 20000 | X10: 이두식 | Y10: 010-9061-3000 | AC10: =365*T10 -> 1825 | AQ10: 아이나비 Z7000 | AR10: 190000 | AT10: 버텍스 전면 35%/1열 15%, 2열, 후면 5% | BD10: 만26세 | BE10: 무한대 | BF10: 5억 | BG10: 2억/3천만 | BH10: 2억원/1인당 | BI10: 50만원 | BJ10: 누구나 | BK10: 5회/년 | BL10: 가입 | BM10: 가입 | BN10: 브랜드보증 외 사용자 부담 | BO10: 브랜드보증 외 사용자 부담 | BR10: =IF(P10<=1600,P10*18,IF(P10<=2500,P10*19,IF(P10>2500,P10*24,20000))) -> 47481 | BS10: 현금 | DI10: 주소 없음
A11: 10 | B11: Benz-005 | C11: 사고대차 | D11: 렌트베네핏/사고대차 | E11: 사고대차 | F11: 010-2723-6802 | G11: E350 | H11: 4M | I11: 88000000 | J11: 2022 | K11: PW/Bl | L11: 가솔린 | M11: W1KZF8GB6MB003853 | N11: 125호2370 | O11: - | P11: 1991 | Q11: 44546 | S11: 44546 | T11: 5 | U11: =IFERROR(S11+AC11, "-") -> 46371 | V11: =IFERROR(DATEDIF(TODAY(), U11, "m"), "-") -> 4 | W11: 20000 | X11: 이지혜 고객님 | Y11: 010-2723-6802 | AC11: =365*T11 -> 1825 | AQ11: 벤츠블랙박스 | AT11: 후푸옵틱 측후면 15% 전면 50% | AU11: 3338644 | AW11: 렌터카 공제 | AX11: 44546 | AY11: =3921450-793880 -> 3127570 | AZ11: 1112380 | BD11: 만26세 | BE11: 무한대 | BF11: 5억 | BG11: 2억/3천만 | BH11: 2억원/1인당 | BI11: 50만원 | BJ11: 누구나 | BK11: 5회/년 | BL11: 가입 | BM11: 가입 | BN11: 브랜드보증 외 사용자 부담 | BO11: 브랜드보증 외 사용자 부담 | BR11: =IF(P11<=1600,P11*18,IF(P11<=2500,P11*19,IF(P11>2500,P11*24,20000))) -> 37829 | BS11: 현금 | DI11: 주소 없음
A12: 11 | B12: GV80-003_1 | C12: 계약변경 | D12: 렌트베네핏/사고대차 | E12: 류형선 회장님 | F12: 010-5245-5206 | G12: GV80 | H12: 3.5T 22인치 SDS2 AWD 25MY 5인승 | I12: 97440000 | J12: 2025 | K12: 비크블랙/슬레이트그레이/보르도브라운/올리브애쉬 | L12: 가솔린 | M12: KMTHC81CDSU296247 | N12: 142호4378 | O12: 컨비니언스패키지(255만),파퓰러패키지(5인승AWD)(540만),파노라마썬루프(140만),뱅앤올룹슨사운드패키지(190만),빌트인캠패키지(85만), 2열컴포트패키지(260만) | P12: 3470 | Q12: 45827 | S12: 45827 | T12: 5 | U12: =IFERROR(S12+AC12, "-") -> 47652 | V12: =IFERROR(DATEDIF(TODAY(), U12, "m"), "-") -> 46 | W12: 30000 | X12: 변종규 주임님 | Y12: 010-6695-2708 | AC12: =365*T12 -> 1825 | AQ12: 빌트인캠 | AR12: 190000 | AT12: 버텍스 전면 35%/1열 15%, 2열, 후면 5% | AW12: 렌터카 공제 | BD12: 만26세 | BE12: 무한대 | BF12: 5억 | BG12: 2억/3천만 | BH12: 2억원/1인당 | BI12: 50만원 | BJ12: 누구나 | BK12: 5회/년 | BL12: 가입 | BM12: 가입 | BN12: 브랜드보증 외 사용자 부담 | BO12: 브랜드보증 외 사용자 부담 | BR12: =IF(P12<=1600,P12*18,IF(P12<=2500,P12*19,IF(P12>2500,P12*24,20000))) -> 83280 | BS12: 현금 | DI12: 주소 없음
A13: 12 | B13: Benz-021 | C13: 사고대차 | D13: 렌트베네핏/사고대차 | E13: 사고대차 | F13: 010-9061-3000 | G13: E450 | H13: 4M EX | I13: 111850000 | J13: 2023 | K13: 그라파이트 그레이/브라운 | L13: 가솔린 | M13: W1KZF5KB7PB136714 | N13: 142호2282 | O13: - | P13: 2999 | Q13: 45229 | S13: 45229 | T13: 5 | U13: =IFERROR(S13+AC13, "-") -> 47054 | V13: =IFERROR(DATEDIF(TODAY(), U13, "m"), "-") -> 27 | W13: 20000 | X13: 이두식 | Y13: 010-9061-3000 | AC13: =365*T13 -> 1825 | AQ13: 벤츠블랙박스 | AR13: - | AT13: 버텍스 전면 35%/측후면 15% | AU13: - | AW13: 렌터카 공제 | AX13: - | AY13: - | AZ13: - | BA13: - | BB13: - | BD13: 만26세 | BE13: 무한대 | BF13: 5억 | BG13: 2억/3천만 | BH13: 2억원/1인당 | BI13: - | BJ13: 누구나 | BK13: - | BL13: 가입 | BM13: 가입 | BN13: - | BO13: - | BP13: - | BR13: =IF(P13<=1600,P13*18,IF(P13<=2500,P13*19,IF(P13>2500,P13*24,20000))) -> 71976 | BS13: 현금 | DI13: 주소 없음
A14: 13 | B14: Benz-023 | C14: 사고대차 | D14: 렌트베네핏/사고대차 | E14: 대표님 차량 | F14: 010-9061-3000 | G14: S400d | H14: 4MATIC | I14: 160600000 | J14: 2022 | K14: Diamond white / 804-Nappa leather sienna brown / black | L14: 디젤 | M14: W1K6F3DB2NA094248 | N14: 240조7789 | O14: - | P14: 2999 | Q14: 44557 | S14: 44557 | T14: 5 | U14: =IFERROR(S14+AC14, "-") -> 46382 | V14: =IFERROR(DATEDIF(TODAY(), U14, "m"), "-") -> 5 | W14: 20000 | X14: 이두식 | Y14: 010-9061-3000 | AC14: =365*T14 -> 1825 | AQ14: 벤츠블랙박스 | AR14: 0 | AT14: 0 | AU14: 0 | AW14: 현대 | BJ14: 누구나 | BK14: 5회/년 | BL14: 가입 | BM14: 가입 | BN14: 브랜드보증 외 사용자 부담 | BO14: 브랜드보증 외 사용자 부담 | BR14: =IF(P14<=1600,P14*18,IF(P14<=2500,P14*19,IF(P14>2500,P14*24,20000))) -> 71976 | BS14: 현금 | DI14: 주소 없음
A15: 14 | B15: Benz-026 | C15: 사고대차 | D15: 렌트베네핏/사고대차 | E15: 사고대차 | F15: 010-9061-3000 | G15: S500 | H15: - | I15: 201330000 | J15: 2025 | K15: 그라파이트 그레이/브라운 | L15: 가솔린 | M15: W1K6G6DB7SA334565 | N15: 142호9168 | O15: - | P15: 2998 | Q15: 45940 | S15: 45940 | T15: 5 | U15: =IFERROR(S15+AC15, "-") -> 47765 | V15: =IFERROR(DATEDIF(TODAY(), U15, "m"), "-") -> 50 | W15: 20000 | X15: 이두식 | Y15: 010-9061-3000 | AC15: =365*T15 -> 1825 | AQ15: 벤츠블랙박스 | AT15: 버텍스 전면 35%/측후면 15% | BD15: 만26세 | BE15: 무한대 | BF15: 3억원 | BG15: 1억원/1500만 | BH15: 2억원/1인당 | BI15: 30만원 | BJ15: 누구나 | BK15: 5회/년 | BL15: 가입 | BM15: 가입 | BN15: 브랜드보증 외 사용자 부담 | BO15: 브랜드보증 외 사용자 부담 | DI15: 주소 없음
A16: 15 | B16: Sportage-002 | C16: 사고대차 | D16: 렌트베네핏/사고대차 | E16: 사고대차 | F16: 010-9061-3000 | G16: 스포티지(H) | H16: 2WD 노블레스 | I16: =38280000+3400000 -> 41680000 | J16: 2026 | K16: 스노우 화이트 펄/브라운 투톤 | L16: 가솔린 | M16: KNAPW81GBTK395645 | N16: 151호1416 | O16: - | P16: 1598 | Q16: 46121 | S16: - | T16: 5 | U16: =IFERROR(S16+AC16, "-") -> - | V16: =IFERROR(DATEDIF(TODAY(), U16, "m"), "-") -> - | W16: - | X16: - | Y16: - | AC16: - | AR16: - | AT16: 버텍스 전면 35%/1열 15%, 2열, 후면 5% | AU16: - | AW16: - | AX16: - | AY16: - | AZ16: - | BA16: - | BB16: - | BC16: - | BD16: 만26세 | BE16: 무한대 | BF16: 3억원 | BG16: 1억원/1500만 | BH16: 2억원/1인당 | BI16: 30만원 | BJ16: 누구나 | BK16: 5회/년 | BL16: 가입 | BM16: 가입 | BN16: 브랜드보증 외 사용자 부담 | BO16: 브랜드보증 외 사용자 부담 | BP16: - | BQ16: - | BR16: - | BS16: - | DI16: 주소 없음
A17: 16 | B17: Ray-001 | C17: 장기렌트 | D17: 신흥정보통신㈜_1 | E17: 이종희 이사님 | F17: 010-3214-0636 | G17: Ray Van | H17: 스탠다드 A/T | I17: 12750000 | J17: 2022 | K17: White/Black | L17: 가솔린 | M17: KNACF911BNT283289 | N17: 101호2182 | O17: - | P17: 998 | Q17: 44494 | R17: 44497 | S17: 44497 | T17: 5 | U17: =IFERROR(S17+AC17, "-") -> 46322 | V17: =IFERROR(DATEDIF(TODAY(), U17, "m"), "-") -> 3 | W17: 20000 | X17: 이성호 | Y17: 010-9698-0404 | Z17: 경광주 | AA17: 경기도 광주시 중앙로 144 (경안동, KT광주지점) 3층 신흥정보통신 | AB17: 44505 | AC17: =365*T17 -> 1825 | AD17: =U17-TODAY() -> 96 | AE17: =VLOOKUP($B17, [1]렌트_계약서번호!$B$3:$E$501, 4, FALSE) -> 21100001 | AF17: 13234421 | AG17: 200000 | AH17: 12688000 | AI17: 0 | AJ17: 2000 | AK17: 461380 | AL17: 0 | AM17: 2000 | AN17: 27000 | AO17: 30000 | AP17: 430000 | AQ17: 0 | AR17: 엠피온 | AS17: 0 | AT17: 루마 전면 없음/측후면 15% | AV17: =SUM(AI17,AJ17,AM17,AN17,AO17, AQ17,AS17+AK17+AL17) -> 522380 | AW17: 렌터카 공제 | AX17: 44494 | AY17: 1138590 | AZ17: 1034460 | BD17: 만26세 | BE17: 무한대 | BF17: 2억원 | BG17: 1억원/1500만 | BH17: 2억원/1인당 | BI17: 30만원 | BJ17: 임직원 | BK17: 5회/년 | BL17: 가입 | BM17: 미가입 | BN17: 브랜드보증 외 사용자 부담 | BO17: 브랜드보증 외 사용자 부담 | BP17: HANKOOK 앞/뒤165 60R14 79H 32만원/18/4 | BR17: =IF(P17<=1600,P17*18,IF(P17<=2500,P17*19,IF(P17>2500,P17*24,20000))) -> 17964 | BS17: 현금 | BX17: =BW17*BV17 -> 0 | BY17: =BX17-BU17 -> 0 | BZ17: 0 | CB17: 5 | CC17: 5 | CD17: 342650 | CE17: =T17*12 -> 60 | CF17: =CE17*CD17 -> 20559000 | CI17: 2506900 | CJ17: 0.04 | CK17: 0.04 | CL17: jhlee@shtel.co.kr | CO17: 0.03 | CQ17: 0 | CR17: 0 | CS17: 0 | CT17: 0 | CU17: 0 | CV17: 0 | CW17: 0 | CX17: 0 | CY17: 0 | CZ17: 0 | DA17: 0 | DB17: =IF(DC17="정수원 실장","기아", IF(DC17="박현식 부장", "현대", IF(DC17="김성진 팀장", "한성", IF(DC17="전석영 부장", "한성", IF(DC17= "박봉호 부장", "모토원",IF(DC17="정원철 부장", "한성")))))) -> 기아 | DC17: 정수원 실장 | DD17: =IF(DC17="정수원 실장","렌트베네핏", IF(DC17="박현식 부장", "렌트베네핏", IF(DC17="김성진 팀장", "청담", IF(DC17="전석영 부장", "방배", IF(DC17= "박봉호 부장", "일산",IF(DC73="정원철 부장", "청담")))))) -> 렌트베네핏 | DH17: 206-85-09469 | DI17: 주소 없음 | DJ17: 0.3 | DK17: 0.2
A18: 16 | B18: Benz-027 | C18: 거래완료 | D18: 렌트베네핏/사고대차 | E18: 사고대차 | F18: 010-9061-3000 | G18: G450d | H18: - | I18: 188662500 | J18: 2026 | K18: BLACK/BROWN | L18: 디젤 | M18: W1NWC1AB4TX071682 | N18: 142호9268 | P18: 2989 | Q18: 46073 | S18: - | T18: 5 | U18: =IFERROR(S18+AC18, "-") -> - | V18: =IFERROR(DATEDIF(TODAY(), U18, "m"), "-") -> - | DI18: 주소 없음
A19: 17 | B19: Ray-002 | C19: 장기렌트 | D19: 신흥정보통신㈜_2 | E19: 이종희 이사님 | F19: 010-3214-0636 | G19: Ray Van | H19: 스탠다드 A/T | I19: 12750000 | J19: 2022 | K19: White/Black | L19: 가솔린 | M19: KNACF911BNT282816 | N19: 101호2165 | O19: - | P19: 998 | Q19: 44494 | R19: 44497 | S19: 44497 | T19: 5 | U19: =IFERROR(S19+AC19, "-") -> 46322 | V19: =IFERROR(DATEDIF(TODAY(), U19, "m"), "-") -> 3 | W19: 20000 | X19: 이진근 | Y19: 010-7234-1114 | Z19: 동두천 | AA19: 경기도 동두천시 중앙로 260 (생연동) KT 동두천지점 2층 신흥정보통신 | AB19: 44505 | AC19: =365*T19 -> 1825 | AD19: =U19-TODAY() -> 96 | AE19: =VLOOKUP($B19, [1]렌트_계약서번호!$B$3:$E$501, 4, FALSE) -> 21100002 | AF19: 13234421 | AG19: 200000 | AH19: 12704000 | AI19: 0 | AJ19: 2000 | AK19: 461960 | AL19: 0 | AM19: 2000 | AN19: 27000 | AO19: 30000 | AP19: 430000 | AQ19: 0 | AR19: 엠피온 | AS19: 0 | AT19: 루마 전면 없음/측후면 15% | AV19: =SUM(AI19,AJ19,AM19,AN19,AO19, AQ19,AS19+AK19+AL19) -> 522960 | AW19: 렌터카 공제 | AX19: 44494 | AY19: 1138590 | AZ19: 1034460 | BD19: 만26세 | BE19: 무한대 | BF19: 2억원 | BG19: 1억원/1500만 | BH19: 2억원/1인당 | BI19: 30만원 | BJ19: 임직원 | BK19: 5회/년 | BL19: 가입 | BM19: 미가입 | BN19: 브랜드보증 외 사용자 부담 | BO19: 브랜드보증 외 사용자 부담 | BP19: HANKOOK 앞/뒤165 60R14 79H | BR19: =IF(P19<=1600,P19*18,IF(P19<=2500,P19*19,IF(P19>2500,P19*24,20000))) -> 17964 | BS19: 현금 | BX19: =BW19*BV19 -> 0 | BY19: =BX19-BU19 -> 0 | BZ19: 0 | CB19: 5 | CC19: 5 | CD19: 342650 | CE19: =T19*12 -> 60 | CF19: =CE19*CD19 -> 20559000 | CI19: 2506900 | CJ19: 0.04 | CK19: 0.04 | CL19: jhlee@shtel.co.kr | CO19: 0.03 | CQ19: 0 | CR19: 0 | CS19: 0 | CT19: 0 | CU19: 0 | CV19: 0 | CW19: 0 | CX19: 0 | CY19: 0 | CZ19: 0 | DA19: 0 | DB19: =IF(DC19="정수원 실장","기아", IF(DC19="박현식 부장", "현대", IF(DC19="김성진 팀장", "한성", IF(DC19="전석영 부장", "한성", IF(DC19= "박봉호 부장", "모토원",IF(DC19="정원철 부장", "한성")))))) -> 기아 | DC19: 정수원 실장 | DD19: =IF(DC19="정수원 실장","렌트베네핏", IF(DC19="박현식 부장", "렌트베네핏", IF(DC19="김성진 팀장", "청담", IF(DC19="전석영 부장", "방배", IF(DC19= "박봉호 부장", "일산",IF(DC75="정원철 부장", "청담")))))) -> 렌트베네핏 | DH19: 206-85-09469 | DI19: 주소 없음 | DJ19: 0.3 | DK19: 0.2
A20: 18 | B20: Ray-003 | C20: 장기렌트 | D20: 신흥정보통신㈜_3 | E20: 이종희 이사님 | F20: 010-3214-0636 | G20: Ray Van | H20: 스탠다드 A/T | I20: 12750000 | J20: 2022 | K20: White/Black | L20: 가솔린 | M20: KNACF911BNT282750 | N20: 101호2175 | O20: - | P20: 998 | Q20: 44494 | R20: 44497 | S20: 44497 | T20: 5 | U20: =IFERROR(S20+AC20, "-") -> 46322 | V20: =IFERROR(DATEDIF(TODAY(), U20, "m"), "-") -> 3 | W20: 20000 | X20: 이진근 | Y20: 010-7234-1114 | Z20: 동두천 | AA20: 경기도 동두천시 중앙로 260 (생연동) KT 동두천지점 2층 신흥정보통신 | AB20: 44505 | AC20: =365*T20 -> 1825 | AD20: =U20-TODAY() -> 96 | AE20: =VLOOKUP($B20, [1]렌트_계약서번호!$B$3:$E$501, 4, FALSE) -> 21100003 | AF20: 13234421 | AG20: 200000 | AH20: 12704000 | AI20: 0 | AJ20: 2000 | AK20: 461960 | AL20: 0 | AM20: 2000 | AN20: 27000 | AO20: 30000 | AP20: 430000 | AQ20: 0 | AR20: 엠피온 | AS20: 0 | AT20: 루마 전면 없음/측후면 15% | AV20: =SUM(AI20,AJ20,AM20,AN20,AO20, AQ20,AS20+AK20+AL20) -> 522960 | AW20: 렌터카 공제 | AX20: 44494 | AY20: 1138590 | AZ20: 1034460 | BD20: 만26세 | BE20: 무한대 | BF20: 2억원 | BG20: 1억원/1500만 | BH20: 2억원/1인당 | BI20: 30만원 | BJ20: 임직원 | BK20: 5회/년 | BL20: 가입 | BM20: 미가입 | BN20: 브랜드보증 외 사용자 부담 | BO20: 브랜드보증 외 사용자 부담 | BP20: HANKOOK 앞/뒤165 60R14 79H | BR20: =IF(P20<=1600,P20*18,IF(P20<=2500,P20*19,IF(P20>2500,P20*24,20000))) -> 17964 | BS20: 현금 | BX20: =BW20*BV20 -> 0 | BY20: =BX20-BU20 -> 0 | BZ20: 0 | CB20: 5 | CC20: 5 | CD20: 342650 | CE20: =T20*12 -> 60 | CF20: =CE20*CD20 -> 20559000 | CI20: 2506900 | CJ20: 0.04 | CK20: 0.04 | CL20: jhlee@shtel.co.kr | CO20: 0.03 | CQ20: 0 | CR20: 0 | CS20: 0 | CT20: 0 | CU20: 0 | CV20: 0 | CW20: 0 | CX20: 0 | CY20: 0 | CZ20: 0 | DA20: 0 | DB20: =IF(DC20="정수원 실장","기아", IF(DC20="박현식 부장", "현대", IF(DC20="김성진 팀장", "한성", IF(DC20="전석영 부장", "한성", IF(DC20= "박봉호 부장", "모토원",IF(DC20="정원철 부장", "한성")))))) -> 기아 | DC20: 정수원 실장 | DD20: =IF(DC20="정수원 실장","렌트베네핏", IF(DC20="박현식 부장", "렌트베네핏", IF(DC20="김성진 팀장", "청담", IF(DC20="전석영 부장", "방배", IF(DC20= "박봉호 부장", "일산",IF(DC76="정원철 부장", "청담")))))) -> 렌트베네핏 | DH20: 206-85-09469 | DI20: 주소 없음 | DJ20: 0.3 | DK20: 0.2
A21: 19 | B21: Ray-004 | C21: 장기렌트 | D21: 신흥정보통신㈜_4 | E21: 이종희 이사님 | F21: 010-3214-0636 | G21: Ray Van | H21: 스탠다드 A/T | I21: 12750000 | J21: 2022 | K21: White/Black | L21: 가솔린 | M21: KNACF911BNT283278 | N21: 101호2174 | O21: - | P21: 998 | Q21: 44494 | R21: 44497 | S21: 44497 | T21: 5 | U21: =IFERROR(S21+AC21, "-") -> 46322 | V21: =IFERROR(DATEDIF(TODAY(), U21, "m"), "-") -> 3 | W21: 20000 | X21: 이진근 | Y21: 010-7234-1114 | Z21: 동두천 | AA21: 경기도 동두천시 중앙로 260 (생연동) KT 동두천지점 2층 신흥정보통신 | AB21: 44505 | AC21: =365*T21 -> 1825 | AD21: =U21-TODAY() -> 96 | AE21: =VLOOKUP($B21, [1]렌트_계약서번호!$B$3:$E$501, 4, FALSE) -> 21100004 | AF21: 13234421 | AG21: 200000 | AH21: 12704000 | AI21: 0 | AJ21: 2000 | AK21: 461960 | AL21: 0 | AM21: 2000 | AN21: 27000 | AO21: 30000 | AP21: 430000 | AQ21: 0 | AR21: 엠피온 | AS21: 0 | AT21: 루마 전면 없음/측후면 15% | AV21: =SUM(AI21,AJ21,AM21,AN21,AO21, AQ21,AS21+AK21+AL21) -> 522960 | AW21: 렌터카 공제 | AX21: 44494 | AY21: 1138590 | AZ21: 1034460 | BD21: 만26세 | BE21: 무한대 | BF21: 2억원 | BG21: 1억원/1500만 | BH21: 2억원/1인당 | BI21: 30만원 | BJ21: 임직원 | BK21: 5회/년 | BL21: 가입 | BM21: 미가입 | BN21: 브랜드보증 외 사용자 부담 | BO21: 브랜드보증 외 사용자 부담 | BP21: HANKOOK 앞/뒤165 60R14 79H | BR21: =IF(P21<=1600,P21*18,IF(P21<=2500,P21*19,IF(P21>2500,P21*24,20000))) -> 17964 | BS21: 현금 | BX21: =BW21*BV21 -> 0 | BY21: =BX21-BU21 -> 0 | BZ21: 0 | CB21: 5 | CC21: 5 | CD21: 342650 | CE21: =T21*12 -> 60 | CF21: =CE21*CD21 -> 20559000 | CI21: 2506900 | CJ21: 0.04 | CK21: 0.04 | CL21: jhlee@shtel.co.kr | CO21: 0.03 | CQ21: 0 | CR21: 0 | CS21: 0 | CT21: 0 | CU21: 0 | CV21: 0 | CW21: 0 | CX21: 0 | CY21: 0 | CZ21: 0 | DA21: 0 | DB21: =IF(DC21="정수원 실장","기아", IF(DC21="박현식 부장", "현대", IF(DC21="김성진 팀장", "한성", IF(DC21="전석영 부장", "한성", IF(DC21= "박봉호 부장", "모토원",IF(DC21="정원철 부장", "한성")))))) -> 기아 | DC21: 정수원 실장 | DD21: =IF(DC21="정수원 실장","렌트베네핏", IF(DC21="박현식 부장", "렌트베네핏", IF(DC21="김성진 팀장", "청담", IF(DC21="전석영 부장", "방배", IF(DC21= "박봉호 부장", "일산",IF([1]렌트_차량관리_거래완료!DC23="정원철 부장", "청담")))))) -> 렌트베네핏 | DH21: 206-85-09469 | DI21: 주소 없음 | DJ21: 0.3 | DK21: 0.2
A22: 20 | B22: Ray-005 | C22: 장기렌트 | D22: 신흥정보통신㈜_5 | E22: 이종희 이사님 | F22: 010-3214-0636 | G22: Ray Van | H22: 스탠다드 A/T | I22: 12750000 | J22: 2022 | K22: White/Black | L22: 가솔린 | M22: KNACF911BNT283303 | N22: 101호2164 | O22: - | P22: 998 | Q22: 44494 | R22: 44497 | S22: 44497 | T22: 5 | U22: =IFERROR(S22+AC22, "-") -> 46322 | V22: =IFERROR(DATEDIF(TODAY(), U22, "m"), "-") -> 3 | W22: 20000 | X22: 이진근 | Y22: 010-7234-1114 | Z22: 동두천 | AA22: 경기도 동두천시 중앙로 260 (생연동) KT 동두천지점 2층 신흥정보통신 | AB22: 44505 | AC22: =365*T22 -> 1825 | AD22: =U22-TODAY() -> 96 | AE22: =VLOOKUP($B22, [1]렌트_계약서번호!$B$3:$E$501, 4, FALSE) -> 21100005 | AF22: 13234421 | AG22: 200000 | AH22: 12704000 | AI22: 0 | AJ22: 2000 | AK22: 461960 | AL22: 0 | AM22: 2000 | AN22: 27000 | AO22: 30000 | AP22: 430000 | AQ22: 0 | AR22: 엠피온 | AS22: 0 | AT22: 루마 전면 없음/측후면 15% | AV22: =SUM(AI22,AJ22,AM22,AN22,AO22, AQ22,AS22+AK22+AL22) -> 522960 | AW22: 렌터카 공제 | AX22: 44494 | AY22: 1138590 | AZ22: 1034460 | BD22: 만26세 | BE22: 무한대 | BF22: 2억원 | BG22: 1억원/1500만 | BH22: 2억원/1인당 | BI22: 30만원 | BJ22: 임직원 | BK22: 5회/년 | BL22: 가입 | BM22: 미가입 | BN22: 브랜드보증 외 사용자 부담 | BO22: 브랜드보증 외 사용자 부담 | BP22: HANKOOK 앞/뒤165 60R14 79H | BR22: =IF(P22<=1600,P22*18,IF(P22<=2500,P22*19,IF(P22>2500,P22*24,20000))) -> 17964 | BS22: 현금 | BX22: =BW22*BV22 -> 0 | BY22: =BX22-BU22 -> 0 | BZ22: 0 | CB22: 5 | CC22: 5 | CD22: 342650 | CE22: =T22*12 -> 60 | CF22: =CE22*CD22 -> 20559000 | CI22: 2506900 | CJ22: 0.04 | CK22: 0.04 | CL22: jhlee@shtel.co.kr | CO22: 0.03 | CQ22: 0 | CR22: 0 | CS22: 0 | CT22: 0 | CU22: 0 | CV22: 0 | CW22: 0 | CX22: 0 | CY22: 0 | CZ22: 0 | DA22: 0 | DB22: =IF(DC22="정수원 실장","기아", IF(DC22="박현식 부장", "현대", IF(DC22="김성진 팀장", "한성", IF(DC22="전석영 부장", "한성", IF(DC22= "박봉호 부장", "모토원",IF(DC22="정원철 부장", "한성")))))) -> 기아 | DC22: 정수원 실장 | DD22: =IF(DC22="정수원 실장","렌트베네핏", IF(DC22="박현식 부장", "렌트베네핏", IF(DC22="김성진 팀장", "청담", IF(DC22="전석영 부장", "방배", IF(DC22= "박봉호 부장", "일산",IF(DC77="정원철 부장", "청담")))))) -> 렌트베네핏 | DH22: 206-85-09469 | DI22: 주소 없음 | DJ22: 0.3 | DK22: 0.2
A23: 21 | B23: Ray-006 | C23: 장기렌트 | D23: 신흥정보통신㈜_6 | E23: 이종희 이사님 | F23: 010-3214-0636 | G23: Ray Van | H23: 스탠다드 A/T | I23: 12750000 | J23: 2022 | K23: White/Black | L23: 가솔린 | M23: KNACF911BNT283296 | N23: 125호8641 | O23: - | P23: 998 | Q23: 44494 | R23: 44497 | S23: 44497 | T23: 5 | U23: =IFERROR(S23+AC23, "-") -> 46322 | V23: =IFERROR(DATEDIF(TODAY(), U23, "m"), "-") -> 3 | W23: 20000 | X23: 이진근 | Y23: 010-7234-1114 | Z23: 동두천 | AA23: 경기도 동두천시 중앙로 260 (생연동) KT 동두천지점 2층 신흥정보통신 | AB23: 44505 | AC23: =365*T23 -> 1825 | AD23: =U23-TODAY() -> 96 | AE23: =VLOOKUP($B23, [1]렌트_계약서번호!$B$3:$E$501, 4, FALSE) -> 21100006 | AF23: 13234421 | AG23: 200000 | AH23: 12704000 | AI23: 0 | AJ23: 2000 | AK23: 461960 | AL23: 0 | AM23: 2000 | AN23: 27000 | AO23: 30000 | AP23: 430000 | AQ23: 0 | AR23: 엠피온 | AS23: 0 | AT23: 루마 전면 없음/측후면 15% | AV23: =SUM(AI23,AJ23,AM23,AN23,AO23, AQ23,AS23+AK23+AL23) -> 522960 | AW23: 렌터카 공제 | AX23: 44494 | AY23: 1138590 | AZ23: 1034460 | BD23: 만26세 | BE23: 무한대 | BF23: 2억원 | BG23: 1억원/1500만 | BH23: 2억원/1인당 | BI23: 30만원 | BJ23: 임직원 | BK23: 5회/년 | BL23: 가입 | BM23: 미가입 | BN23: 브랜드보증 외 사용자 부담 | BO23: 브랜드보증 외 사용자 부담 | BP23: HANKOOK 앞/뒤165 60R14 79H | BR23: =IF(P23<=1600,P23*18,IF(P23<=2500,P23*19,IF(P23>2500,P23*24,20000))) -> 17964 | BS23: 현금 | BX23: =BW23*BV23 -> 0 | BY23: =BX23-BU23 -> 0 | BZ23: 0 | CB23: 5 | CC23: 5 | CD23: 342650 | CE23: =T23*12 -> 60 | CF23: =CE23*CD23 -> 20559000 | CI23: 2506900 | CJ23: 0.04 | CK23: 0.04 | CL23: jhlee@shtel.co.kr | CO23: 0.03 | CQ23: 0 | CR23: 0 | CS23: 0 | CT23: 0 | CU23: 0 | CV23: 0 | CW23: 0 | CX23: 0 | CY23: 0 | CZ23: 0 | DA23: 0 | DB23: =IF(DC23="정수원 실장","기아", IF(DC23="박현식 부장", "현대", IF(DC23="김성진 팀장", "한성", IF(DC23="전석영 부장", "한성", IF(DC23= "박봉호 부장", "모토원",IF(DC23="정원철 부장", "한성")))))) -> 기아 | DC23: 정수원 실장 | DD23: =IF(DC23="정수원 실장","렌트베네핏", IF(DC23="박현식 부장", "렌트베네핏", IF(DC23="김성진 팀장", "청담", IF(DC23="전석영 부장", "방배", IF(DC23= "박봉호 부장", "일산",IF(DC78="정원철 부장", "청담")))))) -> 렌트베네핏 | DH23: 206-85-09469 | DI23: 주소 없음 | DJ23: 0.3 | DK23: 0.2
A24: 22 | B24: Ray-007 | C24: 장기렌트 | D24: 신흥정보통신㈜_7 | E24: 이종희 이사님 | F24: 010-3214-0636 | G24: Ray Van | H24: 스탠다드 A/T | I24: 12750000 | J24: 2022 | K24: White/Black | L24: 가솔린 | M24: KNACF911BNT283313 | N24: 101호2173 | O24: - | P24: 998 | Q24: 44494 | R24: 44497 | S24: 44497 | T24: 5 | U24: =IFERROR(S24+AC24, "-") -> 46322 | V24: =IFERROR(DATEDIF(TODAY(), U24, "m"), "-") -> 3 | W24: 20000 | X24: 이성호 | Y24: 010-9698-0404 | Z24: 경광주 | AA24: 경기도 광주시 중앙로 144 (경안동, KT광주지점) 3층 신흥정보통신 | AB24: 44505 | AC24: =365*T24 -> 1825 | AD24: =U24-TODAY() -> 96 | AE24: =VLOOKUP($B24, [1]렌트_계약서번호!$B$3:$E$501, 4, FALSE) -> 21100007 | AF24: 13234421 | AG24: 200000 | AH24: 12688000 | AI24: 0 | AJ24: 2000 | AK24: 461380 | AL24: 0 | AM24: 2000 | AN24: 27000 | AO24: 30000 | AP24: 430000 | AQ24: 0 | AR24: 엠피온 | AS24: 0 | AT24: 루마 전면 없음/측후면 15% | AV24: =SUM(AI24,AJ24,AM24,AN24,AO24, AQ24,AS24+AK24+AL24) -> 522380 | AW24: 렌터카 공제 | AX24: 44494 | AY24: 1138590 | AZ24: 1034460 | BD24: 만26세 | BE24: 무한대 | BF24: 2억원 | BG24: 1억원/1500만 | BH24: 2억원/1인당 | BI24: 30만원 | BJ24: 임직원 | BK24: 5회/년 | BL24: 가입 | BM24: 미가입 | BN24: 브랜드보증 외 사용자 부담 | BO24: 브랜드보증 외 사용자 부담 | BP24: HANKOOK 앞/뒤165 60R14 79H | BR24: =IF(P24<=1600,P24*18,IF(P24<=2500,P24*19,IF(P24>2500,P24*24,20000))) -> 17964 | BS24: 현금 | BX24: =BW24*BV24 -> 0 | BY24: =BX24-BU24 -> 0 | BZ24: 0 | CB24: 5 | CC24: 5 | CD24: 342650 | CE24: =T24*12 -> 60 | CF24: =CE24*CD24 -> 20559000 | CI24: 2506900 | CJ24: 0.04 | CK24: 0.04 | CL24: jhlee@shtel.co.kr | CO24: 0.03 | CQ24: 0 | CR24: 0 | CS24: 0 | CT24: 0 | CU24: 0 | CV24: 0 | CW24: 0 | CX24: 0 | CY24: 0 | CZ24: 0 | DA24: 0 | DB24: =IF(DC24="정수원 실장","기아", IF(DC24="박현식 부장", "현대", IF(DC24="김성진 팀장", "한성", IF(DC24="전석영 부장", "한성", IF(DC24= "박봉호 부장", "모토원",IF(DC24="정원철 부장", "한성")))))) -> 기아 | DC24: 정수원 실장 | DD24: =IF(DC24="정수원 실장","렌트베네핏", IF(DC24="박현식 부장", "렌트베네핏", IF(DC24="김성진 팀장", "청담", IF(DC24="전석영 부장", "방배", IF(DC24= "박봉호 부장", "일산",IF(DC79="정원철 부장", "청담")))))) -> 렌트베네핏 | DH24: 206-85-09469 | DI24: 주소 없음 | DJ24: 0.3 | DK24: 0.2
A25: 23 | B25: Ray-008 | C25: 장기렌트 | D25: 신흥정보통신㈜_8 | E25: 이종희 이사님 | F25: 010-3214-0636 | G25: Ray Van | H25: 스탠다드 A/T | I25: 12750000 | J25: 2022 | K25: White/Black | L25: 가솔린 | M25: KNACF911BNT283348 | N25: 101호2163 | O25: - | P25: 998 | Q25: 44494 | R25: 44497 | S25: 44497 | T25: 5 | U25: =IFERROR(S25+AC25, "-") -> 46322 | V25: =IFERROR(DATEDIF(TODAY(), U25, "m"), "-") -> 3 | W25: 20000 | X25: 이석환 | Y25: 010-3408-0977 | Z25: 동래 | AA25: 부산광역시 동래구 사직북로48번길 127 (온천동, KT미남지점) 2층 신흥정보통신 | AB25: 44505 | AC25: =365*T25 -> 1825 | AD25: =U25-TODAY() -> 96 | AE25: =VLOOKUP($B25, [1]렌트_계약서번호!$B$3:$E$501, 4, FALSE) -> 21100008 | AF25: 13234421 | AG25: 200000 | AH25: 12799000 | AI25: 0 | AJ25: 2000 | AK25: 465410 | AL25: 0 | AM25: 2000 | AN25: 27000 | AO25: 30000 | AP25: 430000 | AQ25: 0 | AR25: 엠피온 | AS25: 0 | AT25: 루마 전면 없음/측후면 15% | AV25: =SUM(AI25,AJ25,AM25,AN25,AO25, AQ25,AS25+AK25+AL25) -> 526410 | AW25: 렌터카 공제 | AX25: 44494 | AY25: 1138590 | AZ25: 1034460 | BD25: 만26세 | BE25: 무한대 | BF25: 2억원 | BG25: 1억원/1500만 | BH25: 2억원/1인당 | BI25: 30만원 | BJ25: 임직원 | BK25: 5회/년 | BL25: 가입 | BM25: 미가입 | BN25: 브랜드보증 외 사용자 부담 | BO25: 브랜드보증 외 사용자 부담 | BP25: HANKOOK 앞/뒤165 60R14 79H | BR25: =IF(P25<=1600,P25*18,IF(P25<=2500,P25*19,IF(P25>2500,P25*24,20000))) -> 17964 | BS25: 현금 | BX25: =BW25*BV25 -> 0 | BY25: =BX25-BU25 -> 0 | BZ25: 0 | CB25: 5 | CC25: 5 | CD25: 342650 | CE25: =T25*12 -> 60 | CF25: =CE25*CD25 -> 20559000 | CI25: 2506900 | CJ25: 0.04 | CK25: 0.04 | CL25: jhlee@shtel.co.kr | CO25: 0.03 | CQ25: 0 | CR25: 0 | CS25: 0 | CT25: 0 | CU25: 0 | CV25: 0 | CW25: 0 | CX25: 0 | CY25: 0 | CZ25: 0 | DA25: 0 | DB25: =IF(DC25="정수원 실장","기아", IF(DC25="박현식 부장", "현대", IF(DC25="김성진 팀장", "한성", IF(DC25="전석영 부장", "한성", IF(DC25= "박봉호 부장", "모토원",IF(DC25="정원철 부장", "한성")))))) -> 기아 | DC25: 정수원 실장 | DD25: =IF(DC25="정수원 실장","렌트베네핏", IF(DC25="박현식 부장", "렌트베네핏", IF(DC25="김성진 팀장", "청담", IF(DC25="전석영 부장", "방배", IF(DC25= "박봉호 부장", "일산",IF(DC80="정원철 부장", "청담")))))) -> 렌트베네핏 | DH25: 206-85-09469 | DI25: 주소 없음 | DJ25: 0.3 | DK25: 0.2
A26: 24 | B26: Ray-009 | C26: 장기렌트 | D26: 신흥정보통신㈜_9 | E26: 이종희 이사님 | F26: 010-3214-0636 | G26: Ray Van | H26: 스탠다드 A/T | I26: 12750000 | J26: 2022 | K26: White/Black | L26: 가솔린 | M26: KNACF911BNT283350 | N26: 101호2167 | O26: - | P26: 998 | Q26: 44494 | R26: 44497 | S26: 44497 | T26: 5 | U26: =IFERROR(S26+AC26, "-") -> 46322 | V26: =IFERROR(DATEDIF(TODAY(), U26, "m"), "-") -> 3 | W26: 20000 | X26: 이석환 | Y26: 010-3408-0977 | Z26: 동래 | AA26: 부산광역시 동래구 사직북로48번길 127 (온천동, KT미남지점) 2층 신흥정보통신 | AB26: 44505 | AC26: =365*T26 -> 1825 | AD26: =U26-TODAY() -> 96 | AE26: =VLOOKUP($B26, [1]렌트_계약서번호!$B$3:$E$501, 4, FALSE) -> 21100009 | AF26: 13234421 | AG26: 200000 | AH26: 12799000 | AI26: 0 | AJ26: 2000 | AK26: 465410 | AL26: 0 | AM26: 2000 | AN26: 27000 | AO26: 30000 | AP26: 430000 | AQ26: 0 | AR26: 엠피온 | AS26: 0 | AT26: 루마 전면 없음/측후면 15% | AV26: =SUM(AI26,AJ26,AM26,AN26,AO26, AQ26,AS26+AK26+AL26) -> 526410 | AW26: 렌터카 공제 | AX26: 44494 | AY26: 1138590 | AZ26: 1034460 | BD26: 만26세 | BE26: 무한대 | BF26: 2억원 | BG26: 1억원/1500만 | BH26: 2억원/1인당 | BI26: 30만원 | BJ26: 임직원 | BK26: 5회/년 | BL26: 가입 | BM26: 미가입 | BN26: 브랜드보증 외 사용자 부담 | BO26: 브랜드보증 외 사용자 부담 | BP26: HANKOOK 앞/뒤165 60R14 79H | BR26: =IF(P26<=1600,P26*18,IF(P26<=2500,P26*19,IF(P26>2500,P26*24,20000))) -> 17964 | BS26: 현금 | BX26: =BW26*BV26 -> 0 | BY26: =BX26-BU26 -> 0 | BZ26: 0 | CB26: 5 | CC26: 5 | CD26: 342650 | CE26: =T26*12 -> 60 | CF26: =CE26*CD26 -> 20559000 | CI26: 2506900 | CJ26: 0.04 | CK26: 0.04 | CL26: jhlee@shtel.co.kr | CO26: 0.03 | CQ26: 0 | CR26: 0 | CS26: 0 | CT26: 0 | CU26: 0 | CV26: 0 | CW26: 0 | CX26: 0 | CY26: 0 | CZ26: 0 | DA26: 0 | DB26: =IF(DC26="정수원 실장","기아", IF(DC26="박현식 부장", "현대", IF(DC26="김성진 팀장", "한성", IF(DC26="전석영 부장", "한성", IF(DC26= "박봉호 부장", "모토원",IF(DC26="정원철 부장", "한성")))))) -> 기아 | DC26: 정수원 실장 | DD26: =IF(DC26="정수원 실장","렌트베네핏", IF(DC26="박현식 부장", "렌트베네핏", IF(DC26="김성진 팀장", "청담", IF(DC26="전석영 부장", "방배", IF(DC26= "박봉호 부장", "일산",IF(DC81="정원철 부장", "청담")))))) -> 렌트베네핏 | DH26: 206-85-09469 | DI26: 주소 없음 | DJ26: 0.3 | DK26: 0.2
A27: 25 | B27: Ray-010 | C27: 장기렌트 | D27: 신흥정보통신㈜_10 | E27: 이종희 이사님 | F27: 010-3214-0636 | G27: Ray Van | H27: 스탠다드 A/T | I27: 12750000 | J27: 2022 | K27: White/Black | L27: 가솔린 | M27: KNACF911BNT283362 | N27: 101호2176 | O27: - | P27: 998 | Q27: 44494 | R27: 44497 | S27: 44497 | T27: 5 | U27: =IFERROR(S27+AC27, "-") -> 46322 | V27: =IFERROR(DATEDIF(TODAY(), U27, "m"), "-") -> 3 | W27: 20000 | X27: 이석환 | Y27: 010-3408-0977 | Z27: 동래 | AA27: 부산광역시 동래구 사직북로48번길 127 (온천동, KT미남지점) 2층 신흥정보통신 | AB27: 44505 | AC27: =365*T27 -> 1825 | AD27: =U27-TODAY() -> 96 | AE27: =VLOOKUP($B27, [1]렌트_계약서번호!$B$3:$E$501, 4, FALSE) -> 21100010 | AF27: 13234421 | AG27: 200000 | AH27: 12799000 | AI27: 0 | AJ27: 2000 | AK27: 465410 | AL27: 0 | AM27: 2000 | AN27: 27000 | AO27: 30000 | AP27: 430000 | AQ27: 0 | AR27: 엠피온 | AS27: 0 | AT27: 루마 전면 없음/측후면 15% | AV27: =SUM(AI27,AJ27,AM27,AN27,AO27, AQ27,AS27+AK27+AL27) -> 526410 | AW27: 렌터카 공제 | AX27: 44494 | AY27: 1138590 | AZ27: 1034460 | BD27: 만26세 | BE27: 무한대 | BF27: 2억원 | BG27: 1억원/1500만 | BH27: 2억원/1인당 | BI27: 30만원 | BJ27: 임직원 | BK27: 5회/년 | BL27: 가입 | BM27: 미가입 | BN27: 브랜드보증 외 사용자 부담 | BO27: 브랜드보증 외 사용자 부담 | BP27: HANKOOK 앞/뒤165 60R14 79H | BR27: =IF(P27<=1600,P27*18,IF(P27<=2500,P27*19,IF(P27>2500,P27*24,20000))) -> 17964 | BS27: 현금 | BX27: =BW27*BV27 -> 0 | BY27: =BX27-BU27 -> 0 | BZ27: 0 | CB27: 5 | CC27: 5 | CD27: 342650 | CE27: =T27*12 -> 60 | CF27: =CE27*CD27 -> 20559000 | CI27: 2506900 | CJ27: 0.04 | CK27: 0.04 | CL27: jhlee@shtel.co.kr | CO27: 0.03 | CQ27: 0 | CR27: 0 | CS27: 0 | CT27: 0 | CU27: 0 | CV27: 0 | CW27: 0 | CX27: 0 | CY27: 0 | CZ27: 0 | DA27: 0 | DB27: =IF(DC27="정수원 실장","기아", IF(DC27="박현식 부장", "현대", IF(DC27="김성진 팀장", "한성", IF(DC27="전석영 부장", "한성", IF(DC27= "박봉호 부장", "모토원",IF(DC27="정원철 부장", "한성")))))) -> 기아 | DC27: 정수원 실장 | DD27: =IF(DC27="정수원 실장","렌트베네핏", IF(DC27="박현식 부장", "렌트베네핏", IF(DC27="김성진 팀장", "청담", IF(DC27="전석영 부장", "방배", IF(DC27= "박봉호 부장", "일산",IF(DC82="정원철 부장", "청담")))))) -> 렌트베네핏 | DH27: 206-85-09469 | DI27: 주소 없음 | DJ27: 0.3 | DK27: 0.2
A28: 26 | B28: Ray-011 | C28: 장기렌트 | D28: 신흥정보통신㈜_11 | E28: 이종희 이사님 | F28: 010-3214-0636 | G28: Ray Van | H28: 스탠다드 A/T | I28: 12750000 | J28: 2022 | K28: White/Black | L28: 가솔린 | M28: KNACF911BNT283365 | N28: 101호2177 | O28: - | P28: 998 | Q28: 44494 | R28: 44497 | S28: 44497 | T28: 5 | U28: =IFERROR(S28+AC28, "-") -> 46322 | V28: =IFERROR(DATEDIF(TODAY(), U28, "m"), "-") -> 3 | W28: 20000 | X28: 김상덕 | Y28: 010-9800-0189 | Z28: 서부산 | AA28: 부산광역시 중구 중앙대로 136 (중앙동, KT중부산지사) 3층 신흥정보통신 | AB28: 44505 | AC28: =365*T28 -> 1825 | AD28: =U28-TODAY() -> 96 | AE28: =VLOOKUP($B28, [1]렌트_계약서번호!$B$3:$E$501, 4, FALSE) -> 21100011 | AF28: 13234421 | AG28: 200000 | AH28: 12786000 | AI28: 0 | AJ28: 2000 | AK28: 464940 | AL28: 0 | AM28: 2000 | AN28: 27000 | AO28: 30000 | AP28: 430000 | AQ28: 0 | AR28: 엠피온 | AS28: 0 | AT28: 루마 전면 없음/측후면 15% | AV28: =SUM(AI28,AJ28,AM28,AN28,AO28, AQ28,AS28+AK28+AL28) -> 525940 | AW28: 렌터카 공제 | AX28: 44494 | AY28: 1138590 | AZ28: 1034460 | BD28: 만26세 | BE28: 무한대 | BF28: 2억원 | BG28: 1억원/1500만 | BH28: 2억원/1인당 | BI28: 30만원 | BJ28: 임직원 | BK28: 5회/년 | BL28: 가입 | BM28: 미가입 | BN28: 브랜드보증 외 사용자 부담 | BO28: 브랜드보증 외 사용자 부담 | BP28: HANKOOK 앞/뒤165 60R14 79H | BR28: =IF(P28<=1600,P28*18,IF(P28<=2500,P28*19,IF(P28>2500,P28*24,20000))) -> 17964 | BS28: 현금 | BX28: =BW28*BV28 -> 0 | BY28: =BX28-BU28 -> 0 | BZ28: 0 | CB28: 5 | CC28: 5 | CD28: 342650 | CE28: =T28*12 -> 60 | CF28: =CE28*CD28 -> 20559000 | CI28: 2506900 | CJ28: 0.04 | CK28: 0.04 | CL28: jhlee@shtel.co.kr | CO28: 0.03 | CQ28: 0 | CR28: 0 | CS28: 0 | CT28: 0 | CU28: 0 | CV28: 0 | CW28: 0 | CX28: 0 | CY28: 0 | CZ28: 0 | DA28: 0 | DB28: =IF(DC28="정수원 실장","기아", IF(DC28="박현식 부장", "현대", IF(DC28="김성진 팀장", "한성", IF(DC28="전석영 부장", "한성", IF(DC28= "박봉호 부장", "모토원",IF(DC28="정원철 부장", "한성")))))) -> 기아 | DC28: 정수원 실장 | DD28: =IF(DC28="정수원 실장","렌트베네핏", IF(DC28="박현식 부장", "렌트베네핏", IF(DC28="김성진 팀장", "청담", IF(DC28="전석영 부장", "방배", IF(DC28= "박봉호 부장", "일산",IF(DC83="정원철 부장", "청담")))))) -> 렌트베네핏 | DH28: 206-85-09469 | DI28: 주소 없음 | DJ28: 0.3 | DK28: 0.2
A29: 27 | B29: Ray-012 | C29: 장기렌트 | D29: 신흥정보통신㈜_12 | E29: 이종희 이사님 | F29: 010-3214-0636 | G29: Ray Van | H29: 스탠다드 A/T | I29: 12750000 | J29: 2022 | K29: White/Black | L29: 가솔린 | M29: KNACF911BNT283427 | N29: 101호2178 | O29: - | P29: 998 | Q29: 44494 | R29: 44497 | S29: 44497 | T29: 5 | U29: =IFERROR(S29+AC29, "-") -> 46322 | V29: =IFERROR(DATEDIF(TODAY(), U29, "m"), "-") -> 3 | W29: 20000 | X29: 김지호 | Y29: 010-9608-8884 | Z29: 구봉 | AA29: 대전광역시 서구 관저북로 6 (관저동) KT구봉지점 2층 신흥정보통신 | AB29: 44505 | AC29: =365*T29 -> 1825 | AD29: =U29-TODAY() -> 96 | AE29: =VLOOKUP($B29, [1]렌트_계약서번호!$B$3:$E$501, 4, FALSE) -> 21100012 | AF29: 13234421 | AG29: 200000 | AH29: 12682000 | AI29: 0 | AJ29: 2000 | AK29: 461160 | AL29: 0 | AM29: 2000 | AN29: 27000 | AO29: 30000 | AP29: 430000 | AQ29: 0 | AR29: 엠피온 | AS29: 0 | AT29: 루마 전면 없음/측후면 15% | AV29: =SUM(AI29,AJ29,AM29,AN29,AO29, AQ29,AS29+AK29+AL29) -> 522160 | AW29: 렌터카 공제 | AX29: 44494 | AY29: 1138590 | AZ29: 1034460 | BD29: 만26세 | BE29: 무한대 | BF29: 2억원 | BG29: 1억원/1500만 | BH29: 2억원/1인당 | BI29: 30만원 | BJ29: 임직원 | BK29: 5회/년 | BL29: 가입 | BM29: 미가입 | BN29: 브랜드보증 외 사용자 부담 | BO29: 브랜드보증 외 사용자 부담 | BP29: HANKOOK 앞/뒤165 60R14 79H | BR29: =IF(P29<=1600,P29*18,IF(P29<=2500,P29*19,IF(P29>2500,P29*24,20000))) -> 17964 | BS29: 현금 | BX29: =BW29*BV29 -> 0 | BY29: =BX29-BU29 -> 0 | BZ29: 0 | CB29: 5 | CC29: 5 | CD29: 342650 | CE29: =T29*12 -> 60 | CF29: =CE29*CD29 -> 20559000 | CI29: 2506900 | CJ29: 0.04 | CK29: 0.04 | CL29: jhlee@shtel.co.kr | CO29: 0.03 | CQ29: 0 | CR29: 0 | CS29: 0 | CT29: 0 | CU29: 0 | CV29: 0 | CW29: 0 | CX29: 0 | CY29: 0 | CZ29: 0 | DA29: 0 | DB29: =IF(DC29="정수원 실장","기아", IF(DC29="박현식 부장", "현대", IF(DC29="김성진 팀장", "한성", IF(DC29="전석영 부장", "한성", IF(DC29= "박봉호 부장", "모토원",IF(DC29="정원철 부장", "한성")))))) -> 기아 | DC29: 정수원 실장 | DD29: =IF(DC29="정수원 실장","렌트베네핏", IF(DC29="박현식 부장", "렌트베네핏", IF(DC29="김성진 팀장", "청담", IF(DC29="전석영 부장", "방배", IF(DC29= "박봉호 부장", "일산",IF(DC84="정원철 부장", "청담")))))) -> 렌트베네핏 | DH29: 206-85-09469 | DI29: 주소 없음 | DJ29: 0.3 | DK29: 0.2
A30: 28 | B30: Ray-013 | C30: 장기렌트 | D30: 신흥정보통신㈜_13 | E30: 이종희 이사님 | F30: 010-3214-0636 | G30: Ray Van | H30: 스탠다드 A/T | I30: 12750000 | J30: 2022 | K30: White/Black | L30: 가솔린 | M30: KNACF911BNT283366 | N30: 101호2168 | O30: - | P30: 998 | Q30: 44494 | R30: 44497 | S30: 44497 | T30: 5 | U30: =IFERROR(S30+AC30, "-") -> 46322 | V30: =IFERROR(DATEDIF(TODAY(), U30, "m"), "-") -> 3 | W30: 20000 | X30: 김지호 | Y30: 010-9608-8884 | Z30: 구봉 | AA30: 대전광역시 서구 관저북로 6 (관저동) KT구봉지점 2층 신흥정보통신 | AB30: 44505 | AC30: =365*T30 -> 1825 | AD30: =U30-TODAY() -> 96 | AE30: =VLOOKUP($B30, [1]렌트_계약서번호!$B$3:$E$501, 4, FALSE) -> 21100013 | AF30: 13234421 | AG30: 200000 | AH30: 12682000 | AI30: 0 | AJ30: 2000 | AK30: 461160 | AL30: 0 | AM30: 2000 | AN30: 27000 | AO30: 30000 | AP30: 430000 | AQ30: 0 | AR30: 엠피온 | AS30: 0 | AT30: 루마 전면 없음/측후면 15% | AV30: =SUM(AI30,AJ30,AM30,AN30,AO30, AQ30,AS30+AK30+AL30) -> 522160 | AW30: 렌터카 공제 | AX30: 44494 | AY30: 1138590 | AZ30: 1034460 | BD30: 만26세 | BE30: 무한대 | BF30: 2억원 | BG30: 1억원/1500만 | BH30: 2억원/1인당 | BI30: 30만원 | BJ30: 임직원 | BK30: 5회/년 | BL30: 가입 | BM30: 미가입 | BN30: 브랜드보증 외 사용자 부담 | BO30: 브랜드보증 외 사용자 부담 | BP30: HANKOOK 앞/뒤165 60R14 79H | BR30: =IF(P30<=1600,P30*18,IF(P30<=2500,P30*19,IF(P30>2500,P30*24,20000))) -> 17964 | BS30: 현금 | BX30: =BW30*BV30 -> 0 | BY30: =BX30-BU30 -> 0 | BZ30: 0 | CB30: 5 | CC30: 5 | CD30: 342650 | CE30: =T30*12 -> 60 | CF30: =CE30*CD30 -> 20559000 | CI30: 2506900 | CJ30: 0.04 | CK30: 0.04 | CL30: jhlee@shtel.co.kr | CO30: 0.03 | CQ30: 0 | CR30: 0 | CS30: 0 | CT30: 0 | CU30: 0 | CV30: 0 | CW30: 0 | CX30: 0 | CY30: 0 | CZ30: 0 | DA30: 0 | DB30: =IF(DC30="정수원 실장","기아", IF(DC30="박현식 부장", "현대", IF(DC30="김성진 팀장", "한성", IF(DC30="전석영 부장", "한성", IF(DC30= "박봉호 부장", "모토원",IF(DC30="정원철 부장", "한성")))))) -> 기아 | DC30: 정수원 실장 | DD30: =IF(DC30="정수원 실장","렌트베네핏", IF(DC30="박현식 부장", "렌트베네핏", IF(DC30="김성진 팀장", "청담", IF(DC30="전석영 부장", "방배", IF(DC30= "박봉호 부장", "일산",IF(#REF!="정원철 부장", "청담")))))) -> 렌트베네핏 | DH30: 206-85-09469 | DI30: 주소 없음 | DJ30: 0.3 | DK30: 0.2
A31: 29 | B31: Ray-014 | C31: 장기렌트 | D31: 신흥정보통신㈜_14 | E31: 이종희 이사님 | F31: 010-3214-0636 | G31: Ray Van | H31: 스탠다드 A/T | I31: 12750000 | J31: 2022 | K31: White/Black | L31: 가솔린 | M31: KNACF911BNT283483 | N31: 101호2169 | O31: - | P31: 998 | Q31: 44494 | R31: 44497 | S31: 44497 | T31: 5 | U31: =IFERROR(S31+AC31, "-") -> 46322 | V31: =IFERROR(DATEDIF(TODAY(), U31, "m"), "-") -> 3 | W31: 20000 | X31: 남진한 | Y31: 010-3479-8628 | Z31: 서대전 | AA31: 대전광역시 서구 괴정로 72 (괴정동) KT서대전지사 2층 신흥정보통신 | AB31: 44505 | AC31: =365*T31 -> 1825 | AD31: =U31-TODAY() -> 96 | AE31: =VLOOKUP($B31, [1]렌트_계약서번호!$B$3:$E$501, 4, FALSE) -> 21100014 | AF31: 13234421 | AG31: 200000 | AH31: 12682000 | AI31: 0 | AJ31: 2000 | AK31: 461160 | AL31: 0 | AM31: 2000 | AN31: 27000 | AO31: 30000 | AP31: 430000 | AQ31: 0 | AR31: 엠피온 | AS31: 0 | AT31: 루마 전면 없음/측후면 15% | AV31: =SUM(AI31,AJ31,AM31,AN31,AO31, AQ31,AS31+AK31+AL31) -> 522160 | AW31: 렌터카 공제 | AX31: 44494 | AY31: 1138590 | AZ31: 1034460 | BD31: 만26세 | BE31: 무한대 | BF31: 2억원 | BG31: 1억원/1500만 | BH31: 2억원/1인당 | BI31: 30만원 | BJ31: 임직원 | BK31: 5회/년 | BL31: 가입 | BM31: 미가입 | BN31: 브랜드보증 외 사용자 부담 | BO31: 브랜드보증 외 사용자 부담 | BP31: HANKOOK 앞/뒤165 60R14 79H | BR31: =IF(P31<=1600,P31*18,IF(P31<=2500,P31*19,IF(P31>2500,P31*24,20000))) -> 17964 | BS31: 현금 | BX31: =BW31*BV31 -> 0 | BY31: =BX31-BU31 -> 0 | BZ31: 0 | CB31: 5 | CC31: 5 | CD31: 342650 | CE31: =T31*12 -> 60 | CF31: =CE31*CD31 -> 20559000 | CI31: 2506900 | CJ31: 0.04 | CK31: 0.04 | CL31: jhlee@shtel.co.kr | CO31: 0.03 | CQ31: 0 | CR31: 0 | CS31: 0 | CT31: 0 | CU31: 0 | CV31: 0 | CW31: 0 | CX31: 0 | CY31: 0 | CZ31: 0 | DA31: 0 | DB31: =IF(DC31="정수원 실장","기아", IF(DC31="박현식 부장", "현대", IF(DC31="김성진 팀장", "한성", IF(DC31="전석영 부장", "한성", IF(DC31= "박봉호 부장", "모토원",IF(DC31="정원철 부장", "한성")))))) -> 기아 | DC31: 정수원 실장 | DD31: =IF(DC31="정수원 실장","렌트베네핏", IF(DC31="박현식 부장", "렌트베네핏", IF(DC31="김성진 팀장", "청담", IF(DC31="전석영 부장", "방배", IF(DC31= "박봉호 부장", "일산",IF(#REF!="정원철 부장", "청담")))))) -> 렌트베네핏 | DH31: 206-85-09469 | DI31: 주소 없음 | DJ31: 0.3 | DK31: 0.2
A32: 30 | B32: Ray-015 | C32: 장기렌트 | D32: 신흥정보통신㈜_15 | E32: 이종희 이사님 | F32: 010-3214-0636 | G32: Ray Van | H32: 스탠다드 A/T | I32: 12750000 | J32: 2022 | K32: White/Black | L32: 가솔린 | M32: KNACF911BNT283551 | N32: 101호2171 | O32: - | P32: 998 | Q32: 44494 | R32: 44497 | S32: 44497 | T32: 5 | U32: =IFERROR(S32+AC32, "-") -> 46322 | V32: =IFERROR(DATEDIF(TODAY(), U32, "m"), "-") -> 3 | W32: 20000 | X32: 김지호 | Y32: 010-9608-8884 | Z32: 구봉 | AA32: 대전광역시 서구 관저북로 6 (관저동) KT구봉지점 2층 신흥정보통신 | AB32: 44505 | AC32: =365*T32 -> 1825 | AD32: =U32-TODAY() -> 96 | AE32: =VLOOKUP($B32, [1]렌트_계약서번호!$B$3:$E$501, 4, FALSE) -> 21100015 | AF32: 13234421 | AG32: 200000 | AH32: 12682000 | AI32: 0 | AJ32: 2000 | AK32: 461160 | AL32: 0 | AM32: 2000 | AN32: 27000 | AO32: 30000 | AP32: 430000 | AQ32: 0 | AR32: 엠피온 | AS32: 0 | AT32: 루마 전면 없음/측후면 15% | AV32: =SUM(AI32,AJ32,AM32,AN32,AO32, AQ32,AS32+AK32+AL32) -> 522160 | AW32: 렌터카 공제 | AX32: 44494 | AY32: 1138590 | AZ32: 1034460 | BD32: 만26세 | BE32: 무한대 | BF32: 2억원 | BG32: 1억원/1500만 | BH32: 2억원/1인당 | BI32: 30만원 | BJ32: 임직원 | BK32: 5회/년 | BL32: 가입 | BM32: 미가입 | BN32: 브랜드보증 외 사용자 부담 | BO32: 브랜드보증 외 사용자 부담 | BP32: HANKOOK 앞/뒤165 60R14 79H | BR32: =IF(P32<=1600,P32*18,IF(P32<=2500,P32*19,IF(P32>2500,P32*24,20000))) -> 17964 | BS32: 현금 | BX32: =BW32*BV32 -> 0 | BY32: =BX32-BU32 -> 0 | BZ32: 0 | CB32: 5 | CC32: 5 | CD32: 342650 | CE32: =T32*12 -> 60 | CF32: =CE32*CD32 -> 20559000 | CI32: 2506900 | CJ32: 0.04 | CK32: 0.04 | CL32: jhlee@shtel.co.kr | CO32: 0.03 | CQ32: 0 | CR32: 0 | CS32: 0 | CT32: 0 | CU32: 0 | CV32: 0 | CW32: 0 | CX32: 0 | CY32: 0 | CZ32: 0 | DA32: 0 | DB32: =IF(DC32="정수원 실장","기아", IF(DC32="박현식 부장", "현대", IF(DC32="김성진 팀장", "한성", IF(DC32="전석영 부장", "한성", IF(DC32= "박봉호 부장", "모토원",IF(DC32="정원철 부장", "한성")))))) -> 기아 | DC32: 정수원 실장 | DD32: =IF(DC32="정수원 실장","렌트베네핏", IF(DC32="박현식 부장", "렌트베네핏", IF(DC32="김성진 팀장", "청담", IF(DC32="전석영 부장", "방배", IF(DC32= "박봉호 부장", "일산",IF(DC93="정원철 부장", "청담")))))) -> 렌트베네핏 | DH32: 206-85-09469 | DI32: 주소 없음 | DJ32: 0.3 | DK32: 0.2
A33: 31 | B33: Ray-016 | C33: 장기렌트 | D33: 신흥정보통신㈜_16 | E33: 이종희 이사님 | F33: 010-3214-0636 | G33: Ray Van | H33: 스탠다드 A/T | I33: 12750000 | J33: 2022 | K33: White/Black | L33: 가솔린 | M33: KNACF911BNT283500 | N33: 101호2172 | O33: - | P33: 998 | Q33: 44494 | R33: 44497 | S33: 44497 | T33: 5 | U33: =IFERROR(S33+AC33, "-") -> 46322 | V33: =IFERROR(DATEDIF(TODAY(), U33, "m"), "-") -> 3 | W33: 20000 | X33: 남진한 | Y33: 010-3479-8628 | Z33: 서대전 | AA33: 대전광역시 서구 괴정로 72 (괴정동) KT서대전지사 2층 신흥정보통신 | AB33: 44505 | AC33: =365*T33 -> 1825 | AD33: =U33-TODAY() -> 96 | AE33: =VLOOKUP($B33, [1]렌트_계약서번호!$B$3:$E$501, 4, FALSE) -> 21100016 | AF33: 13234421 | AG33: 200000 | AH33: 12682000 | AI33: 0 | AJ33: 2000 | AK33: 461160 | AL33: 0 | AM33: 2000 | AN33: 27000 | AO33: 30000 | AP33: 430000 | AQ33: 0 | AR33: 엠피온 | AS33: 0 | AT33: 루마 전면 없음/측후면 15% | AV33: =SUM(AI33,AJ33,AM33,AN33,AO33, AQ33,AS33+AK33+AL33) -> 522160 | AW33: 렌터카 공제 | AX33: 44494 | AY33: 1138590 | AZ33: 1034460 | BD33: 만26세 | BE33: 무한대 | BF33: 2억원 | BG33: 1억원/1500만 | BH33: 2억원/1인당 | BI33: 30만원 | BJ33: 임직원 | BK33: 5회/년 | BL33: 가입 | BM33: 미가입 | BN33: 브랜드보증 외 사용자 부담 | BO33: 브랜드보증 외 사용자 부담 | BP33: HANKOOK 앞/뒤165 60R14 79H | BR33: =IF(P33<=1600,P33*18,IF(P33<=2500,P33*19,IF(P33>2500,P33*24,20000))) -> 17964 | BS33: 현금 | BX33: =BW33*BV33 -> 0 | BY33: =BX33-BU33 -> 0 | BZ33: 0 | CB33: 5 | CC33: 5 | CD33: 342650 | CE33: =T33*12 -> 60 | CF33: =CE33*CD33 -> 20559000 | CI33: 2506900 | CJ33: 0.04 | CK33: 0.04 | CL33: jhlee@shtel.co.kr | CO33: 0.03 | CQ33: 0 | CR33: 0 | CS33: 0 | CT33: 0 | CU33: 0 | CV33: 0 | CW33: 0 | CX33: 0 | CY33: 0 | CZ33: 0 | DA33: 0 | DB33: =IF(DC33="정수원 실장","기아", IF(DC33="박현식 부장", "현대", IF(DC33="김성진 팀장", "한성", IF(DC33="전석영 부장", "한성", IF(DC33= "박봉호 부장", "모토원",IF(DC33="정원철 부장", "한성")))))) -> 기아 | DC33: 정수원 실장 | DD33: =IF(DC33="정수원 실장","렌트베네핏", IF(DC33="박현식 부장", "렌트베네핏", IF(DC33="김성진 팀장", "청담", IF(DC33="전석영 부장", "방배", IF(DC33= "박봉호 부장", "일산",IF(DC94="정원철 부장", "청담")))))) -> 렌트베네핏 | DH33: 206-85-09469 | DI33: 주소 없음 | DJ33: 0.3 | DK33: 0.2
A34: 32 | B34: Ray-017 | C34: 장기렌트 | D34: 신흥정보통신㈜_17 | E34: 이종희 이사님 | F34: 010-3214-0636 | G34: Ray Van | H34: 스탠다드 A/T | I34: 12750000 | J34: 2022 | K34: White/Black | L34: 가솔린 | M34: KNACF911BNT283506 | N34: 101호2181 | O34: - | P34: 998 | Q34: 44494 | R34: 44497 | S34: 44497 | T34: 5 | U34: =IFERROR(S34+AC34, "-") -> 46322 | V34: =IFERROR(DATEDIF(TODAY(), U34, "m"), "-") -> 3 | W34: 20000 | X34: 남진한 | Y34: 010-3479-8628 | Z34: 서대전 | AB34: 44505 | AC34: =365*T34 -> 1825 | AD34: =U34-TODAY() -> 96 | AE34: =VLOOKUP($B34, [1]렌트_계약서번호!$B$3:$E$501, 4, FALSE) -> 21100017 | AF34: 13234421 | AG34: 200000 | AH34: 12682000 | AI34: 0 | AJ34: 2000 | AK34: 461160 | AL34: 0 | AM34: 2000 | AN34: 27000 | AO34: 30000 | AP34: 430000 | AQ34: 0 | AR34: 엠피온 | AS34: 0 | AT34: 루마 전면 없음/측후면 15% | AV34: =SUM(AI34,AJ34,AM34,AN34,AO34, AQ34,AS34+AK34+AL34) -> 522160 | AW34: 렌터카 공제 | AX34: 44494 | AY34: 1138590 | AZ34: 1034460 | BD34: 만26세 | BE34: 무한대 | BF34: 2억원 | BG34: 1억원/1500만 | BH34: 2억원/1인당 | BI34: 30만원 | BJ34: 임직원 | BK34: 5회/년 | BL34: 가입 | BM34: 미가입 | BN34: 브랜드보증 외 사용자 부담 | BO34: 브랜드보증 외 사용자 부담 | BP34: HANKOOK 앞/뒤165 60R14 79H | BR34: =IF(P34<=1600,P34*18,IF(P34<=2500,P34*19,IF(P34>2500,P34*24,20000))) -> 17964 | BS34: 현금 | BX34: =BW34*BV34 -> 0 | BY34: =BX34-BU34 -> 0 | BZ34: 0 | CB34: 5 | CC34: 5 | CD34: 342650 | CE34: =T34*12 -> 60 | CF34: =CE34*CD34 -> 20559000 | CI34: 2506900 | CJ34: 0.04 | CK34: 0.04 | CL34: jhlee@shtel.co.kr | CO34: 0.03 | CQ34: 0 | CR34: 0 | CS34: 0 | CT34: 0 | CU34: 0 | CV34: 0 | CW34: 0 | CX34: 0 | CY34: 0 | CZ34: 0 | DA34: 0 | DB34: =IF(DC34="정수원 실장","기아", IF(DC34="박현식 부장", "현대", IF(DC34="김성진 팀장", "한성", IF(DC34="전석영 부장", "한성", IF(DC34= "박봉호 부장", "모토원",IF(DC34="정원철 부장", "한성")))))) -> 기아 | DC34: 정수원 실장 | DD34: =IF(DC34="정수원 실장","렌트베네핏", IF(DC34="박현식 부장", "렌트베네핏", IF(DC34="김성진 팀장", "청담", IF(DC34="전석영 부장", "방배", IF(DC34= "박봉호 부장", "일산",IF(#REF!="정원철 부장", "청담")))))) -> 렌트베네핏 | DH34: 206-85-09469 | DI34: 주소 없음 | DJ34: 0.3 | DK34: 0.2
A35: 33 | B35: Ray-018 | C35: 장기렌트 | D35: 신흥정보통신㈜_18 | E35: 이종희 이사님 | F35: 010-3214-0636 | G35: Ray Van | H35: 스탠다드 A/T | I35: 12750000 | J35: 2022 | K35: White/Black | L35: 가솔린 | M35: KNACF911BNT283604 | N35: 101호2170 | O35: - | P35: 998 | Q35: 44494 | R35: 44497 | S35: 44497 | T35: 5 | U35: =IFERROR(S35+AC35, "-") -> 46322 | V35: =IFERROR(DATEDIF(TODAY(), U35, "m"), "-") -> 3 | W35: 20000 | X35: 심재화 | Y35: 010-3456-8940 | Z35: 괴산 | AA35: 충청북도 괴산군 괴산읍 읍내로6길 24 (괴산읍, KT괴산지점) 2층 신흥정보통신 | AB35: 44505 | AC35: =365*T35 -> 1825 | AD35: =U35-TODAY() -> 96 | AE35: =VLOOKUP($B35, [1]렌트_계약서번호!$B$3:$E$501, 4, FALSE) -> 21100018 | AF35: 13234421 | AG35: 200000 | AH35: 12703000 | AI35: 0 | AJ35: 2000 | AK35: 461920 | AL35: 0 | AM35: 2000 | AN35: 27000 | AO35: 30000 | AP35: 430000 | AQ35: 0 | AR35: 엠피온 | AS35: 0 | AT35: 루마 전면 없음/측후면 15% | AV35: =SUM(AI35,AJ35,AM35,AN35,AO35, AQ35,AS35+AK35+AL35) -> 522920 | AW35: 렌터카 공제 | AX35: 44494 | AY35: 1138590 | AZ35: 1034460 | BD35: 만26세 | BE35: 무한대 | BF35: 2억원 | BG35: 1억원/1500만 | BH35: 2억원/1인당 | BI35: 30만원 | BJ35: 임직원 | BK35: 5회/년 | BL35: 가입 | BM35: 미가입 | BN35: 브랜드보증 외 사용자 부담 | BO35: 브랜드보증 외 사용자 부담 | BP35: HANKOOK 앞/뒤165 60R14 79H | BR35: =IF(P35<=1600,P35*18,IF(P35<=2500,P35*19,IF(P35>2500,P35*24,20000))) -> 17964 | BS35: 현금 | BX35: =BW35*BV35 -> 0 | BY35: =BX35-BU35 -> 0 | BZ35: 0 | CB35: 5 | CC35: 5 | CD35: 342650 | CE35: =T35*12 -> 60 | CF35: =CE35*CD35 -> 20559000 | CI35: 2506900 | CJ35: 0.04 | CK35: 0.04 | CL35: jhlee@shtel.co.kr | CO35: 0.03 | CQ35: 0 | CR35: 0 | CS35: 0 | CT35: 0 | CU35: 0 | CV35: 0 | CW35: 0 | CX35: 0 | CY35: 0 | CZ35: 0 | DA35: 0 | DB35: =IF(DC35="정수원 실장","기아", IF(DC35="박현식 부장", "현대", IF(DC35="김성진 팀장", "한성", IF(DC35="전석영 부장", "한성", IF(DC35= "박봉호 부장", "모토원",IF(DC35="정원철 부장", "한성")))))) -> 기아 | DC35: 정수원 실장 | DD35: =IF(DC35="정수원 실장","렌트베네핏", IF(DC35="박현식 부장", "렌트베네핏", IF(DC35="김성진 팀장", "청담", IF(DC35="전석영 부장", "방배", IF(DC35= "박봉호 부장", "일산",IF(DC85="정원철 부장", "청담")))))) -> 렌트베네핏 | DH35: 206-85-09469 | DI35: 주소 없음 | DJ35: 0.3 | DK35: 0.2
A36: 34 | B36: Ray-019 | C36: 장기렌트 | D36: 신흥정보통신㈜_19 | E36: 이종희 이사님 | F36: 010-3214-0636 | G36: Ray Van | H36: 스탠다드 A/T | I36: 12750000 | J36: 2022 | K36: White/Black | L36: 가솔린 | M36: KNACF911BNT283689 | N36: 101호2179 | O36: - | P36: 998 | Q36: 44494 | R36: 44497 | S36: 44497 | T36: 5 | U36: =IFERROR(S36+AC36, "-") -> 46322 | V36: =IFERROR(DATEDIF(TODAY(), U36, "m"), "-") -> 3 | W36: 20000 | X36: 김석기 | Y36: 010-9582-0977 | Z36: 청주 | AA36: 충청북도 청주시 서원구 1순환로1063번길 12 (분평동, KT) KT남청주지점 1층 신흥정보통신 | AB36: 44505 | AC36: =365*T36 -> 1825 | AD36: =U36-TODAY() -> 96 | AE36: =VLOOKUP($B36, [1]렌트_계약서번호!$B$3:$E$501, 4, FALSE) -> 21100019 | AF36: 13234421 | AG36: 200000 | AH36: 12675000 | AI36: 0 | AJ36: 2000 | AK36: 460900 | AL36: 0 | AM36: 2000 | AN36: 27000 | AO36: 30000 | AP36: 430000 | AQ36: 0 | AR36: 엠피온 | AS36: 0 | AT36: 루마 전면 없음/측후면 15% | AV36: =SUM(AI36,AJ36,AM36,AN36,AO36, AQ36,AS36+AK36+AL36) -> 521900 | AW36: 렌터카 공제 | AX36: 44494 | AY36: 1138590 | AZ36: 1034460 | BD36: 만26세 | BE36: 무한대 | BF36: 2억원 | BG36: 1억원/1500만 | BH36: 2억원/1인당 | BI36: 30만원 | BJ36: 임직원 | BK36: 5회/년 | BL36: 가입 | BM36: 미가입 | BN36: 브랜드보증 외 사용자 부담 | BO36: 브랜드보증 외 사용자 부담 | BP36: HANKOOK 앞/뒤165 60R14 79H | BR36: =IF(P36<=1600,P36*18,IF(P36<=2500,P36*19,IF(P36>2500,P36*24,20000))) -> 17964 | BS36: 현금 | BX36: =BW36*BV36 -> 0 | BY36: =BX36-BU36 -> 0 | BZ36: 0 | CB36: 5 | CC36: 5 | CD36: 342650 | CE36: =T36*12 -> 60 | CF36: =CE36*CD36 -> 20559000 | CI36: 2506900 | CJ36: 0.04 | CK36: 0.04 | CL36: jhlee@shtel.co.kr | CO36: 0.03 | CQ36: 0 | CR36: 0 | CS36: 0 | CT36: 0 | CU36: 0 | CV36: 0 | CW36: 0 | CX36: 0 | CY36: 0 | CZ36: 0 | DA36: 0 | DB36: =IF(DC36="정수원 실장","기아", IF(DC36="박현식 부장", "현대", IF(DC36="김성진 팀장", "한성", IF(DC36="전석영 부장", "한성", IF(DC36= "박봉호 부장", "모토원",IF(DC36="정원철 부장", "한성")))))) -> 기아 | DC36: 정수원 실장 | DD36: =IF(DC36="정수원 실장","렌트베네핏", IF(DC36="박현식 부장", "렌트베네핏", IF(DC36="김성진 팀장", "청담", IF(DC36="전석영 부장", "방배", IF(DC36= "박봉호 부장", "일산",IF(#REF!="정원철 부장", "청담")))))) -> 렌트베네핏 | DH36: 206-85-09469 | DI36: 주소 없음 | DJ36: 0.3 | DK36: 0.2
A37: 35 | B37: Ray-020 | C37: 장기렌트 | D37: 신흥정보통신㈜_20 | E37: 이종희 이사님 | F37: 010-3214-0636 | G37: Ray Van | H37: 스탠다드 A/T | I37: 12750000 | J37: 2022 | K37: White/Black | L37: 가솔린 | M37: KNACF911BNT283605 | N37: 101호2180 | O37: - | P37: 998 | Q37: 44494 | R37: 44497 | S37: 44497 | T37: 5 | U37: =IFERROR(S37+AC37, "-") -> 46322 | V37: =IFERROR(DATEDIF(TODAY(), U37, "m"), "-") -> 3 | W37: 20000 | X37: 김석기 | Y37: 010-9582-0977 | Z37: 남청주 | AA37: 충청북도 청주시 서원구 1순환로1063번길 12 (분평동, KT) KT남청주지점 1층 신흥정보통신 | AB37: 44505 | AC37: =365*T37 -> 1825 | AD37: =U37-TODAY() -> 96 | AE37: =VLOOKUP($B37, [1]렌트_계약서번호!$B$3:$E$501, 4, FALSE) -> 21100020 | AF37: 13234421 | AG37: 200000 | AH37: 12675000 | AI37: 0 | AJ37: 2000 | AK37: 460900 | AL37: 0 | AM37: 2000 | AN37: 27000 | AO37: 30000 | AP37: 430000 | AQ37: 0 | AR37: 엠피온 | AS37: 0 | AT37: 루마 전면 없음/측후면 15% | AV37: =SUM(AI37,AJ37,AM37,AN37,AO37, AQ37,AS37+AK37+AL37) -> 521900 | AW37: 렌터카 공제 | AX37: 44494 | AY37: 1138590 | AZ37: 1034460 | BD37: 만26세 | BE37: 무한대 | BF37: 2억원 | BG37: 1억원/1500만 | BH37: 2억원/1인당 | BI37: 30만원 | BJ37: 임직원 | BK37: 5회/년 | BL37: 가입 | BM37: 미가입 | BN37: 브랜드보증 외 사용자 부담 | BO37: 브랜드보증 외 사용자 부담 | BP37: HANKOOK 앞/뒤165 60R14 79H | BR37: =IF(P37<=1600,P37*18,IF(P37<=2500,P37*19,IF(P37>2500,P37*24,20000))) -> 17964 | BS37: 현금 | BX37: =BW37*BV37 -> 0 | BY37: =BX37-BU37 -> 0 | BZ37: 0 | CB37: 5 | CC37: 5 | CD37: 342650 | CE37: =T37*12 -> 60 | CF37: =CE37*CD37 -> 20559000 | CI37: 2506900 | CJ37: 0.04 | CK37: 0.04 | CL37: jhlee@shtel.co.kr | CO37: 0.03 | CQ37: 0 | CR37: 0 | CS37: 0 | CT37: 0 | CU37: 0 | CV37: 0 | CW37: 0 | CX37: 0 | CY37: 0 | CZ37: 0 | DA37: 0 | DB37: =IF(DC37="정수원 실장","기아", IF(DC37="박현식 부장", "현대", IF(DC37="김성진 팀장", "한성", IF(DC37="전석영 부장", "한성", IF(DC37= "박봉호 부장", "모토원",IF(DC37="정원철 부장", "한성")))))) -> 기아 | DC37: 정수원 실장 | DD37: =IF(DC37="정수원 실장","렌트베네핏", IF(DC37="박현식 부장", "렌트베네핏", IF(DC37="김성진 팀장", "청담", IF(DC37="전석영 부장", "방배", IF(DC37= "박봉호 부장", "일산",IF(DC86="정원철 부장", "청담")))))) -> 렌트베네핏 | DH37: 206-85-09469 | DI37: 주소 없음 | DJ37: 0.3 | DK37: 0.2
A38: 36 | B38: Ray-034 | C38: 장기렌트 | D38: ㈜한일티엔에스 | E38: 김동은 사장님 | F38: 010-6236-7466 | G38: Ray Van | H38: 스탠다드 A/T | I38: 12750000 | J38: 2022 | K38: White/Black | L38: 가솔린 | M38: KNACF911BNT284065 | N38: 101호2197 | O38: - | P38: 998 | Q38: 44503 | R38: 44510 | S38: 44510 | T38: 5 | U38: =IFERROR(S38+AC38, "-") -> 46335 | V38: =IFERROR(DATEDIF(TODAY(), U38, "m"), "-") -> 3 | W38: 20000 | X38: 김광덕 대표님 | Y38: 010-6236-7466 | AA38: 서울시 동대문구 천호대로 75길 30-1, 1층(답시리동) | AB38: 44525 | AC38: =365*T38 -> 1825 | AD38: =U38-TODAY() -> 109 | AE38: =VLOOKUP($B38, [1]렌트_계약서번호!$B$3:$E$501, 4, FALSE) -> 22090033 | AF38: 13209603 | AG38: 200000 | AH38: 12688000 | AI38: 0 | AJ38: 2000 | AK38: 461380 | AL38: 0 | AM38: 2000 | AN38: 27000 | AO38: 30000 | AP38: 430000 | AQ38: 0 | AR38: 엠피온 | AS38: 0 | AT38: 루마 전면 없음/측후면 15% | AV38: =SUM(AI38,AJ38,AM38,AN38,AO38, AQ38,AS38+AK38+AL38) -> 522380 | AW38: 렌터카 공제 | AX38: 44503 | AY38: 1153090 | AZ38: 1035460 | BD38: 만26세 | BE38: 무한대 | BF38: 2억원 | BG38: 1억원/1500만 | BH38: 2억원/1인당 | BI38: 30만원 | BJ38: 임직원 | BK38: 5회/년 | BL38: 가입 | BM38: 미가입 | BN38: 브랜드보증 외 사용자 부담 | BO38: 브랜드보증 외 사용자 부담 | BP38: HANKOOK 앞/뒤165 60R14 79H | BR38: =IF(P38<=1600,P38*18,IF(P38<=2500,P38*19,IF(P38>2500,P38*24,20000))) -> 17964 | BS38: 현금 | BX38: =BW38*BV38 -> 0 | BY38: =BX38-BU38 -> 0 | BZ38: 0 | CB38: 25 | CC38: 25 | CD38: 350000 | CE38: =T38*12 -> 60 | CF38: =CE38*CD38 -> 21000000 | CI38: 2506900 | CJ38: 0.077 | CK38: 0.04 | CL38: hanilled@hanmail.net | CM38: tnshanil@hometax.go.kr | CO38: 0.03 | CQ38: 0 | CR38: 0 | CS38: 0 | CT38: 0 | CU38: 0 | CV38: 0 | CW38: 0 | CX38: 0 | CY38: 0 | CZ38: 0 | DA38: 0 | DB38: =IF(DC38="정수원 실장","기아", IF(DC38="박현식 부장", "현대", IF(DC38="김성진 팀장", "한성", IF(DC38="전석영 부장", "한성", IF(DC38= "박봉호 부장", "모토원",IF(DC38="정원철 부장", "한성")))))) -> 기아 | DC38: 정수원 실장 | DD38: =IF(DC38="정수원 실장","렌트베네핏", IF(DC38="박현식 부장", "렌트베네핏", IF(DC38="김성진 팀장", "청담", IF(DC38="전석영 부장", "방배", IF(DC38= "박봉호 부장", "일산",IF(#REF!="정원철 부장", "청담")))))) -> 렌트베네핏 | DH38: 604-86-02503 | DI38: 서울시 동대문구 천호대로 75길 30-1, 1층(답시리동) | DJ38: 0.3 | DK38: 0.2
A39: 37 | B39: Benz-003_1 | C39: 계약변경 | D39: 법무법인(유)화우 | E39: 방기태 변호사님 | F39: 010-8216-3340 | G39: GLE450 | H39: 4M | I39: 118600000 | J39: 2021 | K39: Obsidian Black/Leather black | L39: 가솔린 | M39: W1NFB5KB2MA564614 | N39: 125호2333 | O39: - | P39: 2999 | Q39: 44512 | R39: 44510 | S39: 44513 | T39: 3 | U39: =IFERROR(S39+AC39, "-") -> 45608 | V39: =IFERROR(DATEDIF(TODAY(), U39, "m"), "-") -> - | W39: 20000 | X39: 방기태 변호사님 | Y39: 010-8216-3340 | AA39: 청담전시장 | AB39: 44555 | AC39: =365*T39 -> 1095 | AD39: =U39-TODAY() -> -618 | AE39: =VLOOKUP($B39, [1]렌트_계약서번호!$B$3:$E$501, 4, FALSE) -> 24110003 | AF39: 113856000 | AG39: =AF39-AH39 -> 0 | AH39: 113856000 | AI39: 0 | AJ39: 0 | AK39: 4140210 | AL39: 201254 | AM39: 5000 | AN39: 21500 | AO39: 30000 | AP39: 0 | AQ39: 0 | AR39: 벤츠블랙박스 | AS39: 0 | AT39: 후푸옵틱 측후면 15% 전면 50% | AU39: 4397964 | AV39: =SUM(AI39,AJ39,AM39,AN39,AO39, AQ39,AS39+AK39+AL39) -> 4397964 | AW39: 렌터카 공제 | AX39: 44512 | AY39: =4776960-702160 -> 4074800 | AZ39: 1134440 | BD39: 만26세 | BE39: 무한대 | BF39: 5억 | BG39: 2억/3천만 | BH39: 2억원/1인당 | BI39: 50만원 | BJ39: 임직원 | BK39: 5회/년 | BL39: 가입 | BM39: 미가입 | BN39: 브랜드보증 외 사용자 부담 | BO39: 브랜드보증 외 사용자 부담 | BP39: Bridge stone 앞,뒤 275 50R / 20 | BR39: =IF(P39<=1600,P39*18,IF(P39<=2500,P39*19,IF(P39>2500,P39*24,20000))) -> 71976 | BS39: 메리츠캐피탈 | BT39: 44511 | BU39: 101571000 | BV39: 36 | BW39: 3067700 | BX39: 111382117 | BY39: 9811117 | BZ39: 0.0306 | CB39: 25 | CC39: 15 | CD39: 2932000 | CE39: =T39*12 -> 36 | CF39: =CE39*CD39 -> 105552000 | CG39: 12360000 | CH39: 0 | CI39: 45114000 | CJ39: 0.021 | CK39: 0.06 | CL39: kjk@yoonyang.com | CM39: sjk@hwawoo.com | CO39: 0.03 | CQ39: 0 | CR39: 0 | CS39: 0 | CT39: 0 | CU39: 0 | CV39: 0 | CW39: 0 | CX39: 0 | CY39: 0 | CZ39: 0 | DA39: 0 | DB39: =IF(DC39="정수원 실장","기아", IF(DC39="박현식 부장", "현대", IF(DC39="김성진 팀장", "한성", IF(DC39="전석영 부장", "한성", IF(DC39= "박봉호 부장", "모토원",IF(DC39="정원철 부장", "한성")))))) -> 한성 | DC39: 정원철 부장 | DD39: =IF(DC39="정수원 실장","렌트베네핏", IF(DC39="박현식 부장", "렌트베네핏", IF(DC39="김성진 팀장", "청담", IF(DC39="전석영 부장", "방배", IF(DC39= "박봉호 부장", "일산",IF(DC97="정원철 부장", "청담")))))) -> FALSE | DH39: 120-86-47851 | DI39: 주소 없음 | DJ39: 0.3 | DK39: 0.2
